<?xml version="1.0" ?>
<!-- =================================================================================== -->
<!-- |    This document was autogenerated by xacro from engineer_robot.urdf.xacro      | -->
<!-- |    EDITING THIS FILE BY HAND IS NOT RECOMMENDED                                 | -->
<!-- =================================================================================== -->
<robot name="engineer">
  &gt;

  
  <!-- 深度相机 -->
  <gazebo reference="engineer_depth_camera_link">
    <sensor name="engineer_depth_camera_sensor" type="depth">
      <always_on>1</always_on>
      <update_rate>100</update_rate>
      <camera name="engineer_depth_camera">
        <horizontal_fov>1.3962634</horizontal_fov>
        <image>
          <width>640</width>
          <height>360</height>
          <format>R8G8B8</format>
        </image>
        <clip>
          <near>0.02</near>
          <far>300</far>
        </clip>
        <noise>
          <type>gaussian</type>
          <mean>0.0</mean>
          <stddev>0.007</stddev>
          <!-- 噪声参数 -->
        </noise>
        <distortion>
          <k1>0.0</k1>
          <k2>0.0</k2>
          <k3>0.0</k3>
          <p1>0.0</p1>
          <p2>0.0</p2>
          <center>0.0 0.0</center>
        </distortion>
      </camera>
      <plugin filename="libgazebo_ros_camera.so" name="engineer_depth_camera_plugin">
        <ros>
          <namespace>engineer</namespace>
          <remapping>custom_camera/image_raw:=custom_camera/custom_image</remapping>
          <remapping>custom_camera/image_depth:=custom_camera/custom_image_depth</remapping>
          <remapping>custom_camera/camera_info:=custom_camera/custom_info_raw</remapping>
          <remapping>custom_camera/camera_info_depth:=custom_camera/custom_info_depth</remapping>
          <remapping>custom_camera/points:=custom_camera/custom_points</remapping>
        </ros>
        <camera_name>engineer_depth_camera</camera_name>
        <frame_name>engineer_depth_camera_optical_link</frame_name>
        <hack_baseline>0.07</hack_baseline>
        <min_depth>0.0001</min_depth>
      </plugin>
    </sensor>
  </gazebo>
  <!-- 麦轮 -->
  <gazebo>
    <plugin filename="libgazebo_ros_planar_move.so" name="wheel_controller">
      <ros>
        <namespace>engineer</namespace>
        <remapping>cmd_vel:=cmd_vel</remapping>
        <remapping>odom:=odom</remapping>
      </ros>
      <commandTopic>cmd_vel</commandTopic>
      <odometryTopic>odom</odometryTopic>
      <odometryFrame>odom</odometryFrame>
      <leftFrontJoint>LF_joint</leftFrontJoint>
      <rightFrontJoint>RF_joint</rightFrontJoint>
      <leftRearJoint>LB_joint</leftRearJoint>
      <rightRearJoint>RB_joint</rightRearJoint>
      <odometryRate>100</odometryRate>
      <robotBaseFrame>base_link</robotBaseFrame>
      <broadcastTF>1</broadcastTF>
    </plugin>
  </gazebo>
  <!-- ros2_control -->
  <ros2_control name="GazeboSystem" type="system">
    <hardware>
      <plugin>gazebo_ros2_control/GazeboSystem</plugin>
    </hardware>
    <joint name="LF_joint">
      <command_interface name="position"/>
      <state_interface name="position">
        <param name="initial_value">0</param>
      </state_interface>
      <state_interface name="velocity"/>
    </joint>
    <joint name="RF_joint">
      <command_interface name="position"/>
      <state_interface name="position">
        <param name="initial_value">0</param>
      </state_interface>
      <state_interface name="velocity"/>
    </joint>
    <joint name="RB_joint">
      <command_interface name="position"/>
      <state_interface name="position">
        <param name="initial_value">0</param>
      </state_interface>
      <state_interface name="velocity"/>
    </joint>
    <joint name="LB_joint">
      <command_interface name="position"/>
      <state_interface name="position">
        <param name="initial_value">0</param>
      </state_interface>
      <state_interface name="velocity"/>
    </joint>
    <joint name="link1_joint">
      <command_interface name="position"/>
      <state_interface name="position">
        <param name="initial_value">0</param>
      </state_interface>
      <state_interface name="velocity"/>
    </joint>
    <joint name="link2_joint">
      <command_interface name="position"/>
      <state_interface name="position">
        <param name="initial_value">0</param>
      </state_interface>
      <state_interface name="velocity"/>
    </joint>
    <joint name="link3_joint">
      <command_interface name="position"/>
      <state_interface name="position">
        <param name="initial_value">0</param>
      </state_interface>
      <state_interface name="velocity"/>
    </joint>
    <joint name="link4_joint">
      <command_interface name="position"/>
      <state_interface name="position">
        <param name="initial_value">0</param>
      </state_interface>
      <state_interface name="velocity"/>
    </joint>
    <joint name="link5_joint">
      <command_interface name="position"/>
      <state_interface name="position">
        <param name="initial_value">0</param>
      </state_interface>
      <state_interface name="velocity"/>
    </joint>
    <joint name="link6_joint">
      <command_interface name="position"/>
      <state_interface name="position">
        <param name="initial_value">0</param>
      </state_interface>
      <state_interface name="velocity"/>
    </joint>
    <joint name="link7_joint">
      <command_interface name="position"/>
      <state_interface name="position">
        <param name="initial_value">0</param>
      </state_interface>
      <state_interface name="velocity"/>
    </joint>
    <joint name="left_z_joint">
      <command_interface name="position"/>
      <state_interface name="position">
        <param name="initial_value">0</param>
      </state_interface>
      <state_interface name="velocity"/>
    </joint>
    <joint name="left_x_joint">
      <command_interface name="position"/>
      <state_interface name="position">
        <param name="initial_value">0</param>
      </state_interface>
      <state_interface name="velocity"/>
    </joint>
    <joint name="left_yaw_joint">
      <command_interface name="position"/>
      <state_interface name="position">
        <param name="initial_value">0</param>
      </state_interface>
      <state_interface name="velocity"/>
    </joint>
    <joint name="right_z_joint">
      <command_interface name="position"/>
      <state_interface name="position">
        <param name="initial_value">0</param>
      </state_interface>
      <state_interface name="velocity"/>
    </joint>
    <joint name="right_x_joint">
      <command_interface name="position"/>
      <state_interface name="position">
        <param name="initial_value">0</param>
      </state_interface>
      <state_interface name="velocity"/>
    </joint>
    <joint name="right_yaw_joint">
      <command_interface name="position"/>
      <state_interface name="position">
        <param name="initial_value">0</param>
      </state_interface>
      <state_interface name="velocity"/>
    </joint>
  </ros2_control>
  <!-- 加载ros2_control插件 -->
  <gazebo>
    <plugin filename="libgazebo_ros2_control.so" name="engineer_ros2_control">
      <ros>
        <namespace>engineer</namespace>
      </ros>
      <parameters>/media/linji/d/Ubuntu22.04/ros2_ws/install/engineer_gazebo_sim/share/engineer_gazebo_sim/gazebo_classic/config/engineer_ros2_controllers.yaml</parameters>
      <robot_param>robot_description</robot_param>
      <robot_param_node>robot_state_publisher</robot_param_node>
    </plugin>
  </gazebo>
  <!-- <link name="world"/>
  <joint name="base_joint" type="planar">
    <origin rpy="0 0 0" xyz="0 0 0"/>
    <parent link="world"/>
    <child link="base_link"/>
    <axis xyz="0 0 0"/>
  </joint> -->
  <link name="base_link">
    <inertial>
      <origin rpy="0 0 0" xyz="0.005227 0.003946 0.069171"/>
      <mass value="11.8124"/>
      <inertia ixx="0.460669" ixy="-0.020119" ixz="0.002386" iyy="0.348855" iyz="0.003757" izz="0.666791"/>
    </inertial>
    <visual>
      <origin rpy="0 0 0" xyz="0 0 0"/>
      <geometry>
        <mesh filename="package://engineer_description/meshes/base_link.STL"/>
      </geometry>
      <material name="">
        <color rgba="0.752941176470588 0.752941176470588 0.752941176470588 1"/>
      </material>
    </visual>
    <collision>
      <origin rpy="0 0 0" xyz="0 0 0"/>
      <geometry>
        <mesh filename="package://engineer_description/meshes/base_link.STL"/>
      </geometry>
    </collision>
  </link>
  <joint name="LF_joint" type="continuous">
    <parent link="base_link"/>
    <child link="wheel_LF"/>
    <origin rpy="-1.5708 0 0" xyz="0.20286 0.2023 -0.012411"/>
    <axis xyz="0 0 1"/>
    <!-- <dynamics damping="3.0" friction="5.0"/> -->
  </joint>
  <link name="wheel_LF">
    <visual>
      <origin rpy="0 0 0" xyz="0 0 0"/>
      <geometry>
        <mesh filename="package://engineer_description/meshes/right-threaded_mecanum_wheel_wheel.STL"/>
      </geometry>
      <material name="white">
        <color rgba="1.0 1.0 1.0 1.0"/>
      </material>
    </visual>
    <collision>
      <origin rpy="0 0 0" xyz="0 0 0"/>
      <geometry>
        <mesh filename="package://engineer_description/meshes/right-threaded_mecanum_wheel_wheel.STL"/>
      </geometry>
    </collision>
    <inertial>
      <origin rpy="0 0 0" xyz="0 0 0"/>
      <mass value="0.007056"/>
      <inertia ixx="0.000017" ixy="0" ixz="0" iyy="0.000017" iyz="0" izz="0.000033"/>
    </inertial>
  </link>
  <joint name="roller_LF_1_joint" type="continuous">
    <parent link="wheel_LF"/>
    <child link="roller_LF_1_link"/>
    <origin rpy="-0.7854 0 0.106101" xyz="0.0665813309591685 0.007090974485087869 0.0019"/>
    <axis xyz="0 0 1"/>
    <dynamics damping="0.0" friction="0.0"/>
  </joint>
  <link name="roller_LF_1_link">
    <visual>
      <origin rpy="0 0 0" xyz="0 0 0"/>
      <geometry>
        <mesh filename="package://engineer_description/meshes/roller.STL"/>
      </geometry>
      <material name="gray">
        <color rgba="0.5 0.5 0.5 1.0"/>
      </material>
    </visual>
    <collision>
      <origin rpy="0 0 0" xyz="0 0 0"/>
      <geometry>
        <mesh filename="package://engineer_description/meshes/roller.STL"/>
      </geometry>
    </collision>
    <inertial>
      <origin rpy="0 0 0" xyz="0 0 0"/>
      <mass value="0.008738"/>
      <inertia ixx="0.000001" ixy="0" ixz="0" iyy="0.000001" iyz="0" izz="0.000001"/>
    </inertial>
  </link>
  <joint name="roller_LF_2_joint" type="continuous">
    <parent link="wheel_LF"/>
    <child link="roller_LF_2_link"/>
    <origin rpy="-0.7854 0 0.4988" xyz="0.05879953308264269 0.03203077365137633 0.0019"/>
    <axis xyz="0 0 1"/>
    <dynamics damping="0.0" friction="0.0"/>
  </joint>
  <link name="roller_LF_2_link">
    <visual>
      <origin rpy="0 0 0" xyz="0 0 0"/>
      <geometry>
        <mesh filename="package://engineer_description/meshes/roller.STL"/>
      </geometry>
      <material name="gray">
        <color rgba="0.5 0.5 0.5 1.0"/>
      </material>
    </visual>
    <collision>
      <origin rpy="0 0 0" xyz="0 0 0"/>
      <geometry>
        <mesh filename="package://engineer_description/meshes/roller.STL"/>
      </geometry>
    </collision>
    <inertial>
      <origin rpy="0 0 0" xyz="0 0 0"/>
      <mass value="0.008738"/>
      <inertia ixx="0.000001" ixy="0" ixz="0" iyy="0.000001" iyz="0" izz="0.000001"/>
    </inertial>
  </link>
  <joint name="roller_LF_3_joint" type="continuous">
    <parent link="wheel_LF"/>
    <child link="roller_LF_3_link"/>
    <origin rpy="-0.7854 0 0.891499" xyz="0.04206604299008407 0.0520941798917969 0.0019"/>
    <axis xyz="0 0 1"/>
    <dynamics damping="0.0" friction="0.0"/>
  </joint>
  <link name="roller_LF_3_link">
    <visual>
      <origin rpy="0 0 0" xyz="0 0 0"/>
      <geometry>
        <mesh filename="package://engineer_description/meshes/roller.STL"/>
      </geometry>
      <material name="gray">
        <color rgba="0.5 0.5 0.5 1.0"/>
      </material>
    </visual>
    <collision>
      <origin rpy="0 0 0" xyz="0 0 0"/>
      <geometry>
        <mesh filename="package://engineer_description/meshes/roller.STL"/>
      </geometry>
    </collision>
    <inertial>
      <origin rpy="0 0 0" xyz="0 0 0"/>
      <mass value="0.008738"/>
      <inertia ixx="0.000001" ixy="0" ixz="0" iyy="0.000001" iyz="0" izz="0.000001"/>
    </inertial>
  </link>
  <joint name="roller_LF_4_joint" type="continuous">
    <parent link="wheel_LF"/>
    <child link="roller_LF_4_link"/>
    <origin rpy="-0.7854 0 1.284198" xyz="0.018928381812282655 0.06422672273603056 0.0019"/>
    <axis xyz="0 0 1"/>
    <dynamics damping="0.0" friction="0.0"/>
  </joint>
  <link name="roller_LF_4_link">
    <visual>
      <origin rpy="0 0 0" xyz="0 0 0"/>
      <geometry>
        <mesh filename="package://engineer_description/meshes/roller.STL"/>
      </geometry>
      <material name="gray">
        <color rgba="0.5 0.5 0.5 1.0"/>
      </material>
    </visual>
    <collision>
      <origin rpy="0 0 0" xyz="0 0 0"/>
      <geometry>
        <mesh filename="package://engineer_description/meshes/roller.STL"/>
      </geometry>
    </collision>
    <inertial>
      <origin rpy="0 0 0" xyz="0 0 0"/>
      <mass value="0.008738"/>
      <inertia ixx="0.000001" ixy="0" ixz="0" iyy="0.000001" iyz="0" izz="0.000001"/>
    </inertial>
  </link>
  <joint name="roller_LF_5_joint" type="continuous">
    <parent link="wheel_LF"/>
    <child link="roller_LF_5_link"/>
    <origin rpy="-0.7854 0 1.676897" xyz="-0.007090952726648328 0.06658133327645922 0.0019"/>
    <axis xyz="0 0 1"/>
    <dynamics damping="0.0" friction="0.0"/>
  </joint>
  <link name="roller_LF_5_link">
    <visual>
      <origin rpy="0 0 0" xyz="0 0 0"/>
      <geometry>
        <mesh filename="package://engineer_description/meshes/roller.STL"/>
      </geometry>
      <material name="gray">
        <color rgba="0.5 0.5 0.5 1.0"/>
      </material>
    </visual>
    <collision>
      <origin rpy="0 0 0" xyz="0 0 0"/>
      <geometry>
        <mesh filename="package://engineer_description/meshes/roller.STL"/>
      </geometry>
    </collision>
    <inertial>
      <origin rpy="0 0 0" xyz="0 0 0"/>
      <mass value="0.008738"/>
      <inertia ixx="0.000001" ixy="0" ixz="0" iyy="0.000001" iyz="0" izz="0.000001"/>
    </inertial>
  </link>
  <joint name="roller_LF_6_joint" type="continuous">
    <parent link="wheel_LF"/>
    <child link="roller_LF_6_link"/>
    <origin rpy="-0.7854 0 2.069596" xyz="-0.032030754435987296 0.058799543550132914 0.0019"/>
    <axis xyz="0 0 1"/>
    <dynamics damping="0.0" friction="0.0"/>
  </joint>
  <link name="roller_LF_6_link">
    <visual>
      <origin rpy="0 0 0" xyz="0 0 0"/>
      <geometry>
        <mesh filename="package://engineer_description/meshes/roller.STL"/>
      </geometry>
      <material name="gray">
        <color rgba="0.5 0.5 0.5 1.0"/>
      </material>
    </visual>
    <collision>
      <origin rpy="0 0 0" xyz="0 0 0"/>
      <geometry>
        <mesh filename="package://engineer_description/meshes/roller.STL"/>
      </geometry>
    </collision>
    <inertial>
      <origin rpy="0 0 0" xyz="0 0 0"/>
      <mass value="0.008738"/>
      <inertia ixx="0.000001" ixy="0" ixz="0" iyy="0.000001" iyz="0" izz="0.000001"/>
    </inertial>
  </link>
  <joint name="roller_LF_7_joint" type="continuous">
    <parent link="wheel_LF"/>
    <child link="roller_LF_7_link"/>
    <origin rpy="-0.7854 0 2.462295" xyz="-0.05209416614482594 0.042066060014193954 0.0019"/>
    <axis xyz="0 0 1"/>
    <dynamics damping="0.0" friction="0.0"/>
  </joint>
  <link name="roller_LF_7_link">
    <visual>
      <origin rpy="0 0 0" xyz="0 0 0"/>
      <geometry>
        <mesh filename="package://engineer_description/meshes/roller.STL"/>
      </geometry>
      <material name="gray">
        <color rgba="0.5 0.5 0.5 1.0"/>
      </material>
    </visual>
    <collision>
      <origin rpy="0 0 0" xyz="0 0 0"/>
      <geometry>
        <mesh filename="package://engineer_description/meshes/roller.STL"/>
      </geometry>
    </collision>
    <inertial>
      <origin rpy="0 0 0" xyz="0 0 0"/>
      <mass value="0.008738"/>
      <inertia ixx="0.000001" ixy="0" ixz="0" iyy="0.000001" iyz="0" izz="0.000001"/>
    </inertial>
  </link>
  <joint name="roller_LF_8_joint" type="continuous">
    <parent link="wheel_LF"/>
    <child link="roller_LF_8_link"/>
    <origin rpy="-0.7854 0 2.854994" xyz="-0.06422671655032855 0.018928402801246857 0.0019"/>
    <axis xyz="0 0 1"/>
    <dynamics damping="0.0" friction="0.0"/>
  </joint>
  <link name="roller_LF_8_link">
    <visual>
      <origin rpy="0 0 0" xyz="0 0 0"/>
      <geometry>
        <mesh filename="package://engineer_description/meshes/roller.STL"/>
      </geometry>
      <material name="gray">
        <color rgba="0.5 0.5 0.5 1.0"/>
      </material>
    </visual>
    <collision>
      <origin rpy="0 0 0" xyz="0 0 0"/>
      <geometry>
        <mesh filename="package://engineer_description/meshes/roller.STL"/>
      </geometry>
    </collision>
    <inertial>
      <origin rpy="0 0 0" xyz="0 0 0"/>
      <mass value="0.008738"/>
      <inertia ixx="0.000001" ixy="0" ixz="0" iyy="0.000001" iyz="0" izz="0.000001"/>
    </inertial>
  </link>
  <joint name="roller_LF_9_joint" type="continuous">
    <parent link="wheel_LF"/>
    <child link="roller_LF_9_link"/>
    <origin rpy="-0.7854 0 3.247694" xyz="-0.06658132850277856 -0.007090997549540072 0.0019"/>
    <axis xyz="0 0 1"/>
    <dynamics damping="0.0" friction="0.0"/>
  </joint>
  <link name="roller_LF_9_link">
    <visual>
      <origin rpy="0 0 0" xyz="0 0 0"/>
      <geometry>
        <mesh filename="package://engineer_description/meshes/roller.STL"/>
      </geometry>
      <material name="gray">
        <color rgba="0.5 0.5 0.5 1.0"/>
      </material>
    </visual>
    <collision>
      <origin rpy="0 0 0" xyz="0 0 0"/>
      <geometry>
        <mesh filename="package://engineer_description/meshes/roller.STL"/>
      </geometry>
    </collision>
    <inertial>
      <origin rpy="0 0 0" xyz="0 0 0"/>
      <mass value="0.008738"/>
      <inertia ixx="0.000001" ixy="0" ixz="0" iyy="0.000001" iyz="0" izz="0.000001"/>
    </inertial>
  </link>
  <joint name="roller_LF_10_joint" type="continuous">
    <parent link="wheel_LF"/>
    <child link="roller_LF_10_link"/>
    <origin rpy="-0.7854 0 3.640393" xyz="-0.058799521986852246 -0.03203079402013282 0.0019"/>
    <axis xyz="0 0 1"/>
    <dynamics damping="0.0" friction="0.0"/>
  </joint>
  <link name="roller_LF_10_link">
    <visual>
      <origin rpy="0 0 0" xyz="0 0 0"/>
      <geometry>
        <mesh filename="package://engineer_description/meshes/roller.STL"/>
      </geometry>
      <material name="gray">
        <color rgba="0.5 0.5 0.5 1.0"/>
      </material>
    </visual>
    <collision>
      <origin rpy="0 0 0" xyz="0 0 0"/>
      <geometry>
        <mesh filename="package://engineer_description/meshes/roller.STL"/>
      </geometry>
    </collision>
    <inertial>
      <origin rpy="0 0 0" xyz="0 0 0"/>
      <mass value="0.008738"/>
      <inertia ixx="0.000001" ixy="0" ixz="0" iyy="0.000001" iyz="0" izz="0.000001"/>
    </inertial>
  </link>
  <joint name="roller_LF_11_joint" type="continuous">
    <parent link="wheel_LF"/>
    <child link="roller_LF_11_link"/>
    <origin rpy="-0.7854 0 4.033092" xyz="-0.04206602494412593 -0.052094194463900415 0.0019"/>
    <axis xyz="0 0 1"/>
    <dynamics damping="0.0" friction="0.0"/>
  </joint>
  <link name="roller_LF_11_link">
    <visual>
      <origin rpy="0 0 0" xyz="0 0 0"/>
      <geometry>
        <mesh filename="package://engineer_description/meshes/roller.STL"/>
      </geometry>
      <material name="gray">
        <color rgba="0.5 0.5 0.5 1.0"/>
      </material>
    </visual>
    <collision>
      <origin rpy="0 0 0" xyz="0 0 0"/>
      <geometry>
        <mesh filename="package://engineer_description/meshes/roller.STL"/>
      </geometry>
    </collision>
    <inertial>
      <origin rpy="0 0 0" xyz="0 0 0"/>
      <mass value="0.008738"/>
      <inertia ixx="0.000001" ixy="0" ixz="0" iyy="0.000001" iyz="0" izz="0.000001"/>
    </inertial>
  </link>
  <joint name="roller_LF_12_joint" type="continuous">
    <parent link="wheel_LF"/>
    <child link="roller_LF_12_link"/>
    <origin rpy="-0.7854 0 4.425791" xyz="-0.0189283595634892 -0.06422672929301136 0.0019"/>
    <axis xyz="0 0 1"/>
    <dynamics damping="0.0" friction="0.0"/>
  </joint>
  <link name="roller_LF_12_link">
    <visual>
      <origin rpy="0 0 0" xyz="0 0 0"/>
      <geometry>
        <mesh filename="package://engineer_description/meshes/roller.STL"/>
      </geometry>
      <material name="gray">
        <color rgba="0.5 0.5 0.5 1.0"/>
      </material>
    </visual>
    <collision>
      <origin rpy="0 0 0" xyz="0 0 0"/>
      <geometry>
        <mesh filename="package://engineer_description/meshes/roller.STL"/>
      </geometry>
    </collision>
    <inertial>
      <origin rpy="0 0 0" xyz="0 0 0"/>
      <mass value="0.008738"/>
      <inertia ixx="0.000001" ixy="0" ixz="0" iyy="0.000001" iyz="0" izz="0.000001"/>
    </inertial>
  </link>
  <joint name="roller_LF_13_joint" type="continuous">
    <parent link="wheel_LF"/>
    <child link="roller_LF_13_link"/>
    <origin rpy="-0.7854 0 4.81849" xyz="0.007090975791101305 -0.06658133082007683 0.0019"/>
    <axis xyz="0 0 1"/>
    <dynamics damping="0.0" friction="0.0"/>
  </joint>
  <link name="roller_LF_13_link">
    <visual>
      <origin rpy="0 0 0" xyz="0 0 0"/>
      <geometry>
        <mesh filename="package://engineer_description/meshes/roller.STL"/>
      </geometry>
      <material name="gray">
        <color rgba="0.5 0.5 0.5 1.0"/>
      </material>
    </visual>
    <collision>
      <origin rpy="0 0 0" xyz="0 0 0"/>
      <geometry>
        <mesh filename="package://engineer_description/meshes/roller.STL"/>
      </geometry>
    </collision>
    <inertial>
      <origin rpy="0 0 0" xyz="0 0 0"/>
      <mass value="0.008738"/>
      <inertia ixx="0.000001" ixy="0" ixz="0" iyy="0.000001" iyz="0" izz="0.000001"/>
    </inertial>
  </link>
  <joint name="roller_LF_14_joint" type="continuous">
    <parent link="wheel_LF"/>
    <child link="roller_LF_14_link"/>
    <origin rpy="-0.7854 0 5.211189" xyz="0.03203077480474741 -0.05879953245434912 0.0019"/>
    <axis xyz="0 0 1"/>
    <dynamics damping="0.0" friction="0.0"/>
  </joint>
  <link name="roller_LF_14_link">
    <visual>
      <origin rpy="0 0 0" xyz="0 0 0"/>
      <geometry>
        <mesh filename="package://engineer_description/meshes/roller.STL"/>
      </geometry>
      <material name="gray">
        <color rgba="0.5 0.5 0.5 1.0"/>
      </material>
    </visual>
    <collision>
      <origin rpy="0 0 0" xyz="0 0 0"/>
      <geometry>
        <mesh filename="package://engineer_description/meshes/roller.STL"/>
      </geometry>
    </collision>
    <inertial>
      <origin rpy="0 0 0" xyz="0 0 0"/>
      <mass value="0.008738"/>
      <inertia ixx="0.000001" ixy="0" ixz="0" iyy="0.000001" iyz="0" izz="0.000001"/>
    </inertial>
  </link>
  <joint name="roller_LF_15_joint" type="continuous">
    <parent link="wheel_LF"/>
    <child link="roller_LF_15_link"/>
    <origin rpy="-0.7854 0 5.603888" xyz="0.052094180716935376 -0.04206604196824054 0.0019"/>
    <axis xyz="0 0 1"/>
    <dynamics damping="0.0" friction="0.0"/>
  </joint>
  <link name="roller_LF_15_link">
    <visual>
      <origin rpy="0 0 0" xyz="0 0 0"/>
      <geometry>
        <mesh filename="package://engineer_description/meshes/roller.STL"/>
      </geometry>
      <material name="gray">
        <color rgba="0.5 0.5 0.5 1.0"/>
      </material>
    </visual>
    <collision>
      <origin rpy="0 0 0" xyz="0 0 0"/>
      <geometry>
        <mesh filename="package://engineer_description/meshes/roller.STL"/>
      </geometry>
    </collision>
    <inertial>
      <origin rpy="0 0 0" xyz="0 0 0"/>
      <mass value="0.008738"/>
      <inertia ixx="0.000001" ixy="0" ixz="0" iyy="0.000001" iyz="0" izz="0.000001"/>
    </inertial>
  </link>
  <joint name="roller_LF_16_joint" type="continuous">
    <parent link="wheel_LF"/>
    <child link="roller_LF_16_link"/>
    <origin rpy="-0.7854 0 5.996587" xyz="0.06422672310731661 -0.01892838055245557 0.0019"/>
    <axis xyz="0 0 1"/>
    <dynamics damping="0.0" friction="0.0"/>
  </joint>
  <link name="roller_LF_16_link">
    <visual>
      <origin rpy="0 0 0" xyz="0 0 0"/>
      <geometry>
        <mesh filename="package://engineer_description/meshes/roller.STL"/>
      </geometry>
      <material name="gray">
        <color rgba="0.5 0.5 0.5 1.0"/>
      </material>
    </visual>
    <collision>
      <origin rpy="0 0 0" xyz="0 0 0"/>
      <geometry>
        <mesh filename="package://engineer_description/meshes/roller.STL"/>
      </geometry>
    </collision>
    <inertial>
      <origin rpy="0 0 0" xyz="0 0 0"/>
      <mass value="0.008738"/>
      <inertia ixx="0.000001" ixy="0" ixz="0" iyy="0.000001" iyz="0" izz="0.000001"/>
    </inertial>
  </link>
  <joint name="RF_joint" type="continuous">
    <parent link="base_link"/>
    <child link="wheel_RF"/>
    <origin rpy="-1.5708 0 0" xyz="0.20286 -0.2023 -0.012411"/>
    <axis xyz="0 0 1"/>
    <!-- <dynamics damping="3.0" friction="5.0"/> -->
  </joint>
  <link name="wheel_RF">
    <visual>
      <origin rpy="0 0 0" xyz="0 0 0"/>
      <geometry>
        <mesh filename="package://engineer_description/meshes/left-threaded_mecanum_wheel_wheel.STL"/>
      </geometry>
      <material name="white">
        <color rgba="1.0 1.0 1.0 1.0"/>
      </material>
    </visual>
    <collision>
      <origin rpy="0 0 0" xyz="0 0 0"/>
      <geometry>
        <mesh filename="package://engineer_description/meshes/left-threaded_mecanum_wheel_wheel.STL"/>
      </geometry>
    </collision>
    <inertial>
      <origin rpy="0 0 0" xyz="0 0 0"/>
      <mass value="0.007056"/>
      <inertia ixx="0.000017" ixy="0" ixz="0" iyy="0.000017" iyz="0" izz="0.000033"/>
    </inertial>
  </link>
  <joint name="roller_RF_1_joint" type="continuous">
    <parent link="wheel_RF"/>
    <child link="roller_RF_1_link"/>
    <origin rpy="0.7854 0 0.106101" xyz="0.0665813309591685 0.007090974485087869 -0.0019"/>
    <axis xyz="0 0 1"/>
    <dynamics damping="0.0" friction="0.0"/>
  </joint>
  <link name="roller_RF_1_link">
    <visual>
      <origin rpy="0 0 0" xyz="0 0 0"/>
      <geometry>
        <mesh filename="package://engineer_description/meshes/roller.STL"/>
      </geometry>
      <material name="gray">
        <color rgba="0.5 0.5 0.5 1.0"/>
      </material>
    </visual>
    <collision>
      <origin rpy="0 0 0" xyz="0 0 0"/>
      <geometry>
        <mesh filename="package://engineer_description/meshes/roller.STL"/>
      </geometry>
    </collision>
    <inertial>
      <origin rpy="0 0 0" xyz="0 0 0"/>
      <mass value="0.008738"/>
      <inertia ixx="0.000001" ixy="0" ixz="0" iyy="0.000001" iyz="0" izz="0.000001"/>
    </inertial>
  </link>
  <joint name="roller_RF_2_joint" type="continuous">
    <parent link="wheel_RF"/>
    <child link="roller_RF_2_link"/>
    <origin rpy="0.7854 0 0.4988" xyz="0.05879953308264269 0.03203077365137633 -0.0019"/>
    <axis xyz="0 0 1"/>
    <dynamics damping="0.0" friction="0.0"/>
  </joint>
  <link name="roller_RF_2_link">
    <visual>
      <origin rpy="0 0 0" xyz="0 0 0"/>
      <geometry>
        <mesh filename="package://engineer_description/meshes/roller.STL"/>
      </geometry>
      <material name="gray">
        <color rgba="0.5 0.5 0.5 1.0"/>
      </material>
    </visual>
    <collision>
      <origin rpy="0 0 0" xyz="0 0 0"/>
      <geometry>
        <mesh filename="package://engineer_description/meshes/roller.STL"/>
      </geometry>
    </collision>
    <inertial>
      <origin rpy="0 0 0" xyz="0 0 0"/>
      <mass value="0.008738"/>
      <inertia ixx="0.000001" ixy="0" ixz="0" iyy="0.000001" iyz="0" izz="0.000001"/>
    </inertial>
  </link>
  <joint name="roller_RF_3_joint" type="continuous">
    <parent link="wheel_RF"/>
    <child link="roller_RF_3_link"/>
    <origin rpy="0.7854 0 0.891499" xyz="0.04206604299008407 0.0520941798917969 -0.0019"/>
    <axis xyz="0 0 1"/>
    <dynamics damping="0.0" friction="0.0"/>
  </joint>
  <link name="roller_RF_3_link">
    <visual>
      <origin rpy="0 0 0" xyz="0 0 0"/>
      <geometry>
        <mesh filename="package://engineer_description/meshes/roller.STL"/>
      </geometry>
      <material name="gray">
        <color rgba="0.5 0.5 0.5 1.0"/>
      </material>
    </visual>
    <collision>
      <origin rpy="0 0 0" xyz="0 0 0"/>
      <geometry>
        <mesh filename="package://engineer_description/meshes/roller.STL"/>
      </geometry>
    </collision>
    <inertial>
      <origin rpy="0 0 0" xyz="0 0 0"/>
      <mass value="0.008738"/>
      <inertia ixx="0.000001" ixy="0" ixz="0" iyy="0.000001" iyz="0" izz="0.000001"/>
    </inertial>
  </link>
  <joint name="roller_RF_4_joint" type="continuous">
    <parent link="wheel_RF"/>
    <child link="roller_RF_4_link"/>
    <origin rpy="0.7854 0 1.284198" xyz="0.018928381812282655 0.06422672273603056 -0.0019"/>
    <axis xyz="0 0 1"/>
    <dynamics damping="0.0" friction="0.0"/>
  </joint>
  <link name="roller_RF_4_link">
    <visual>
      <origin rpy="0 0 0" xyz="0 0 0"/>
      <geometry>
        <mesh filename="package://engineer_description/meshes/roller.STL"/>
      </geometry>
      <material name="gray">
        <color rgba="0.5 0.5 0.5 1.0"/>
      </material>
    </visual>
    <collision>
      <origin rpy="0 0 0" xyz="0 0 0"/>
      <geometry>
        <mesh filename="package://engineer_description/meshes/roller.STL"/>
      </geometry>
    </collision>
    <inertial>
      <origin rpy="0 0 0" xyz="0 0 0"/>
      <mass value="0.008738"/>
      <inertia ixx="0.000001" ixy="0" ixz="0" iyy="0.000001" iyz="0" izz="0.000001"/>
    </inertial>
  </link>
  <joint name="roller_RF_5_joint" type="continuous">
    <parent link="wheel_RF"/>
    <child link="roller_RF_5_link"/>
    <origin rpy="0.7854 0 1.676897" xyz="-0.007090952726648328 0.06658133327645922 -0.0019"/>
    <axis xyz="0 0 1"/>
    <dynamics damping="0.0" friction="0.0"/>
  </joint>
  <link name="roller_RF_5_link">
    <visual>
      <origin rpy="0 0 0" xyz="0 0 0"/>
      <geometry>
        <mesh filename="package://engineer_description/meshes/roller.STL"/>
      </geometry>
      <material name="gray">
        <color rgba="0.5 0.5 0.5 1.0"/>
      </material>
    </visual>
    <collision>
      <origin rpy="0 0 0" xyz="0 0 0"/>
      <geometry>
        <mesh filename="package://engineer_description/meshes/roller.STL"/>
      </geometry>
    </collision>
    <inertial>
      <origin rpy="0 0 0" xyz="0 0 0"/>
      <mass value="0.008738"/>
      <inertia ixx="0.000001" ixy="0" ixz="0" iyy="0.000001" iyz="0" izz="0.000001"/>
    </inertial>
  </link>
  <joint name="roller_RF_6_joint" type="continuous">
    <parent link="wheel_RF"/>
    <child link="roller_RF_6_link"/>
    <origin rpy="0.7854 0 2.069596" xyz="-0.032030754435987296 0.058799543550132914 -0.0019"/>
    <axis xyz="0 0 1"/>
    <dynamics damping="0.0" friction="0.0"/>
  </joint>
  <link name="roller_RF_6_link">
    <visual>
      <origin rpy="0 0 0" xyz="0 0 0"/>
      <geometry>
        <mesh filename="package://engineer_description/meshes/roller.STL"/>
      </geometry>
      <material name="gray">
        <color rgba="0.5 0.5 0.5 1.0"/>
      </material>
    </visual>
    <collision>
      <origin rpy="0 0 0" xyz="0 0 0"/>
      <geometry>
        <mesh filename="package://engineer_description/meshes/roller.STL"/>
      </geometry>
    </collision>
    <inertial>
      <origin rpy="0 0 0" xyz="0 0 0"/>
      <mass value="0.008738"/>
      <inertia ixx="0.000001" ixy="0" ixz="0" iyy="0.000001" iyz="0" izz="0.000001"/>
    </inertial>
  </link>
  <joint name="roller_RF_7_joint" type="continuous">
    <parent link="wheel_RF"/>
    <child link="roller_RF_7_link"/>
    <origin rpy="0.7854 0 2.462295" xyz="-0.05209416614482594 0.042066060014193954 -0.0019"/>
    <axis xyz="0 0 1"/>
    <dynamics damping="0.0" friction="0.0"/>
  </joint>
  <link name="roller_RF_7_link">
    <visual>
      <origin rpy="0 0 0" xyz="0 0 0"/>
      <geometry>
        <mesh filename="package://engineer_description/meshes/roller.STL"/>
      </geometry>
      <material name="gray">
        <color rgba="0.5 0.5 0.5 1.0"/>
      </material>
    </visual>
    <collision>
      <origin rpy="0 0 0" xyz="0 0 0"/>
      <geometry>
        <mesh filename="package://engineer_description/meshes/roller.STL"/>
      </geometry>
    </collision>
    <inertial>
      <origin rpy="0 0 0" xyz="0 0 0"/>
      <mass value="0.008738"/>
      <inertia ixx="0.000001" ixy="0" ixz="0" iyy="0.000001" iyz="0" izz="0.000001"/>
    </inertial>
  </link>
  <joint name="roller_RF_8_joint" type="continuous">
    <parent link="wheel_RF"/>
    <child link="roller_RF_8_link"/>
    <origin rpy="0.7854 0 2.854994" xyz="-0.06422671655032855 0.018928402801246857 -0.0019"/>
    <axis xyz="0 0 1"/>
    <dynamics damping="0.0" friction="0.0"/>
  </joint>
  <link name="roller_RF_8_link">
    <visual>
      <origin rpy="0 0 0" xyz="0 0 0"/>
      <geometry>
        <mesh filename="package://engineer_description/meshes/roller.STL"/>
      </geometry>
      <material name="gray">
        <color rgba="0.5 0.5 0.5 1.0"/>
      </material>
    </visual>
    <collision>
      <origin rpy="0 0 0" xyz="0 0 0"/>
      <geometry>
        <mesh filename="package://engineer_description/meshes/roller.STL"/>
      </geometry>
    </collision>
    <inertial>
      <origin rpy="0 0 0" xyz="0 0 0"/>
      <mass value="0.008738"/>
      <inertia ixx="0.000001" ixy="0" ixz="0" iyy="0.000001" iyz="0" izz="0.000001"/>
    </inertial>
  </link>
  <joint name="roller_RF_9_joint" type="continuous">
    <parent link="wheel_RF"/>
    <child link="roller_RF_9_link"/>
    <origin rpy="0.7854 0 3.247694" xyz="-0.06658132850277856 -0.007090997549540072 -0.0019"/>
    <axis xyz="0 0 1"/>
    <dynamics damping="0.0" friction="0.0"/>
  </joint>
  <link name="roller_RF_9_link">
    <visual>
      <origin rpy="0 0 0" xyz="0 0 0"/>
      <geometry>
        <mesh filename="package://engineer_description/meshes/roller.STL"/>
      </geometry>
      <material name="gray">
        <color rgba="0.5 0.5 0.5 1.0"/>
      </material>
    </visual>
    <collision>
      <origin rpy="0 0 0" xyz="0 0 0"/>
      <geometry>
        <mesh filename="package://engineer_description/meshes/roller.STL"/>
      </geometry>
    </collision>
    <inertial>
      <origin rpy="0 0 0" xyz="0 0 0"/>
      <mass value="0.008738"/>
      <inertia ixx="0.000001" ixy="0" ixz="0" iyy="0.000001" iyz="0" izz="0.000001"/>
    </inertial>
  </link>
  <joint name="roller_RF_10_joint" type="continuous">
    <parent link="wheel_RF"/>
    <child link="roller_RF_10_link"/>
    <origin rpy="0.7854 0 3.640393" xyz="-0.058799521986852246 -0.03203079402013282 -0.0019"/>
    <axis xyz="0 0 1"/>
    <dynamics damping="0.0" friction="0.0"/>
  </joint>
  <link name="roller_RF_10_link">
    <visual>
      <origin rpy="0 0 0" xyz="0 0 0"/>
      <geometry>
        <mesh filename="package://engineer_description/meshes/roller.STL"/>
      </geometry>
      <material name="gray">
        <color rgba="0.5 0.5 0.5 1.0"/>
      </material>
    </visual>
    <collision>
      <origin rpy="0 0 0" xyz="0 0 0"/>
      <geometry>
        <mesh filename="package://engineer_description/meshes/roller.STL"/>
      </geometry>
    </collision>
    <inertial>
      <origin rpy="0 0 0" xyz="0 0 0"/>
      <mass value="0.008738"/>
      <inertia ixx="0.000001" ixy="0" ixz="0" iyy="0.000001" iyz="0" izz="0.000001"/>
    </inertial>
  </link>
  <joint name="roller_RF_11_joint" type="continuous">
    <parent link="wheel_RF"/>
    <child link="roller_RF_11_link"/>
    <origin rpy="0.7854 0 4.033092" xyz="-0.04206602494412593 -0.052094194463900415 -0.0019"/>
    <axis xyz="0 0 1"/>
    <dynamics damping="0.0" friction="0.0"/>
  </joint>
  <link name="roller_RF_11_link">
    <visual>
      <origin rpy="0 0 0" xyz="0 0 0"/>
      <geometry>
        <mesh filename="package://engineer_description/meshes/roller.STL"/>
      </geometry>
      <material name="gray">
        <color rgba="0.5 0.5 0.5 1.0"/>
      </material>
    </visual>
    <collision>
      <origin rpy="0 0 0" xyz="0 0 0"/>
      <geometry>
        <mesh filename="package://engineer_description/meshes/roller.STL"/>
      </geometry>
    </collision>
    <inertial>
      <origin rpy="0 0 0" xyz="0 0 0"/>
      <mass value="0.008738"/>
      <inertia ixx="0.000001" ixy="0" ixz="0" iyy="0.000001" iyz="0" izz="0.000001"/>
    </inertial>
  </link>
  <joint name="roller_RF_12_joint" type="continuous">
    <parent link="wheel_RF"/>
    <child link="roller_RF_12_link"/>
    <origin rpy="0.7854 0 4.425791" xyz="-0.0189283595634892 -0.06422672929301136 -0.0019"/>
    <axis xyz="0 0 1"/>
    <dynamics damping="0.0" friction="0.0"/>
  </joint>
  <link name="roller_RF_12_link">
    <visual>
      <origin rpy="0 0 0" xyz="0 0 0"/>
      <geometry>
        <mesh filename="package://engineer_description/meshes/roller.STL"/>
      </geometry>
      <material name="gray">
        <color rgba="0.5 0.5 0.5 1.0"/>
      </material>
    </visual>
    <collision>
      <origin rpy="0 0 0" xyz="0 0 0"/>
      <geometry>
        <mesh filename="package://engineer_description/meshes/roller.STL"/>
      </geometry>
    </collision>
    <inertial>
      <origin rpy="0 0 0" xyz="0 0 0"/>
      <mass value="0.008738"/>
      <inertia ixx="0.000001" ixy="0" ixz="0" iyy="0.000001" iyz="0" izz="0.000001"/>
    </inertial>
  </link>
  <joint name="roller_RF_13_joint" type="continuous">
    <parent link="wheel_RF"/>
    <child link="roller_RF_13_link"/>
    <origin rpy="0.7854 0 4.81849" xyz="0.007090975791101305 -0.06658133082007683 -0.0019"/>
    <axis xyz="0 0 1"/>
    <dynamics damping="0.0" friction="0.0"/>
  </joint>
  <link name="roller_RF_13_link">
    <visual>
      <origin rpy="0 0 0" xyz="0 0 0"/>
      <geometry>
        <mesh filename="package://engineer_description/meshes/roller.STL"/>
      </geometry>
      <material name="gray">
        <color rgba="0.5 0.5 0.5 1.0"/>
      </material>
    </visual>
    <collision>
      <origin rpy="0 0 0" xyz="0 0 0"/>
      <geometry>
        <mesh filename="package://engineer_description/meshes/roller.STL"/>
      </geometry>
    </collision>
    <inertial>
      <origin rpy="0 0 0" xyz="0 0 0"/>
      <mass value="0.008738"/>
      <inertia ixx="0.000001" ixy="0" ixz="0" iyy="0.000001" iyz="0" izz="0.000001"/>
    </inertial>
  </link>
  <joint name="roller_RF_14_joint" type="continuous">
    <parent link="wheel_RF"/>
    <child link="roller_RF_14_link"/>
    <origin rpy="0.7854 0 5.211189" xyz="0.03203077480474741 -0.05879953245434912 -0.0019"/>
    <axis xyz="0 0 1"/>
    <dynamics damping="0.0" friction="0.0"/>
  </joint>
  <link name="roller_RF_14_link">
    <visual>
      <origin rpy="0 0 0" xyz="0 0 0"/>
      <geometry>
        <mesh filename="package://engineer_description/meshes/roller.STL"/>
      </geometry>
      <material name="gray">
        <color rgba="0.5 0.5 0.5 1.0"/>
      </material>
    </visual>
    <collision>
      <origin rpy="0 0 0" xyz="0 0 0"/>
      <geometry>
        <mesh filename="package://engineer_description/meshes/roller.STL"/>
      </geometry>
    </collision>
    <inertial>
      <origin rpy="0 0 0" xyz="0 0 0"/>
      <mass value="0.008738"/>
      <inertia ixx="0.000001" ixy="0" ixz="0" iyy="0.000001" iyz="0" izz="0.000001"/>
    </inertial>
  </link>
  <joint name="roller_RF_15_joint" type="continuous">
    <parent link="wheel_RF"/>
    <child link="roller_RF_15_link"/>
    <origin rpy="0.7854 0 5.603888" xyz="0.052094180716935376 -0.04206604196824054 -0.0019"/>
    <axis xyz="0 0 1"/>
    <dynamics damping="0.0" friction="0.0"/>
  </joint>
  <link name="roller_RF_15_link">
    <visual>
      <origin rpy="0 0 0" xyz="0 0 0"/>
      <geometry>
        <mesh filename="package://engineer_description/meshes/roller.STL"/>
      </geometry>
      <material name="gray">
        <color rgba="0.5 0.5 0.5 1.0"/>
      </material>
    </visual>
    <collision>
      <origin rpy="0 0 0" xyz="0 0 0"/>
      <geometry>
        <mesh filename="package://engineer_description/meshes/roller.STL"/>
      </geometry>
    </collision>
    <inertial>
      <origin rpy="0 0 0" xyz="0 0 0"/>
      <mass value="0.008738"/>
      <inertia ixx="0.000001" ixy="0" ixz="0" iyy="0.000001" iyz="0" izz="0.000001"/>
    </inertial>
  </link>
  <joint name="roller_RF_16_joint" type="continuous">
    <parent link="wheel_RF"/>
    <child link="roller_RF_16_link"/>
    <origin rpy="0.7854 0 5.996587" xyz="0.06422672310731661 -0.01892838055245557 -0.0019"/>
    <axis xyz="0 0 1"/>
    <dynamics damping="0.0" friction="0.0"/>
  </joint>
  <link name="roller_RF_16_link">
    <visual>
      <origin rpy="0 0 0" xyz="0 0 0"/>
      <geometry>
        <mesh filename="package://engineer_description/meshes/roller.STL"/>
      </geometry>
      <material name="gray">
        <color rgba="0.5 0.5 0.5 1.0"/>
      </material>
    </visual>
    <collision>
      <origin rpy="0 0 0" xyz="0 0 0"/>
      <geometry>
        <mesh filename="package://engineer_description/meshes/roller.STL"/>
      </geometry>
    </collision>
    <inertial>
      <origin rpy="0 0 0" xyz="0 0 0"/>
      <mass value="0.008738"/>
      <inertia ixx="0.000001" ixy="0" ixz="0" iyy="0.000001" iyz="0" izz="0.000001"/>
    </inertial>
  </link>
  <joint name="RB_joint" type="continuous">
    <parent link="base_link"/>
    <child link="wheel_RB"/>
    <origin rpy="-1.5708 0 0" xyz="-0.20286 -0.2023 -0.012411"/>
    <axis xyz="0 0 1"/>
    <!-- <dynamics damping="3.0" friction="5.0"/> -->
  </joint>
  <link name="wheel_RB">
    <visual>
      <origin rpy="0 0 0" xyz="0 0 0"/>
      <geometry>
        <mesh filename="package://engineer_description/meshes/right-threaded_mecanum_wheel_wheel.STL"/>
      </geometry>
      <material name="white">
        <color rgba="1.0 1.0 1.0 1.0"/>
      </material>
    </visual>
    <collision>
      <origin rpy="0 0 0" xyz="0 0 0"/>
      <geometry>
        <mesh filename="package://engineer_description/meshes/right-threaded_mecanum_wheel_wheel.STL"/>
      </geometry>
    </collision>
    <inertial>
      <origin rpy="0 0 0" xyz="0 0 0"/>
      <mass value="0.007056"/>
      <inertia ixx="0.000017" ixy="0" ixz="0" iyy="0.000017" iyz="0" izz="0.000033"/>
    </inertial>
  </link>
  <joint name="roller_RB_1_joint" type="continuous">
    <parent link="wheel_RB"/>
    <child link="roller_RB_1_link"/>
    <origin rpy="-0.7854 0 0.106101" xyz="0.0665813309591685 0.007090974485087869 0.0019"/>
    <axis xyz="0 0 1"/>
    <dynamics damping="0.0" friction="0.0"/>
  </joint>
  <link name="roller_RB_1_link">
    <visual>
      <origin rpy="0 0 0" xyz="0 0 0"/>
      <geometry>
        <mesh filename="package://engineer_description/meshes/roller.STL"/>
      </geometry>
      <material name="gray">
        <color rgba="0.5 0.5 0.5 1.0"/>
      </material>
    </visual>
    <collision>
      <origin rpy="0 0 0" xyz="0 0 0"/>
      <geometry>
        <mesh filename="package://engineer_description/meshes/roller.STL"/>
      </geometry>
    </collision>
    <inertial>
      <origin rpy="0 0 0" xyz="0 0 0"/>
      <mass value="0.008738"/>
      <inertia ixx="0.000001" ixy="0" ixz="0" iyy="0.000001" iyz="0" izz="0.000001"/>
    </inertial>
  </link>
  <joint name="roller_RB_2_joint" type="continuous">
    <parent link="wheel_RB"/>
    <child link="roller_RB_2_link"/>
    <origin rpy="-0.7854 0 0.4988" xyz="0.05879953308264269 0.03203077365137633 0.0019"/>
    <axis xyz="0 0 1"/>
    <dynamics damping="0.0" friction="0.0"/>
  </joint>
  <link name="roller_RB_2_link">
    <visual>
      <origin rpy="0 0 0" xyz="0 0 0"/>
      <geometry>
        <mesh filename="package://engineer_description/meshes/roller.STL"/>
      </geometry>
      <material name="gray">
        <color rgba="0.5 0.5 0.5 1.0"/>
      </material>
    </visual>
    <collision>
      <origin rpy="0 0 0" xyz="0 0 0"/>
      <geometry>
        <mesh filename="package://engineer_description/meshes/roller.STL"/>
      </geometry>
    </collision>
    <inertial>
      <origin rpy="0 0 0" xyz="0 0 0"/>
      <mass value="0.008738"/>
      <inertia ixx="0.000001" ixy="0" ixz="0" iyy="0.000001" iyz="0" izz="0.000001"/>
    </inertial>
  </link>
  <joint name="roller_RB_3_joint" type="continuous">
    <parent link="wheel_RB"/>
    <child link="roller_RB_3_link"/>
    <origin rpy="-0.7854 0 0.891499" xyz="0.04206604299008407 0.0520941798917969 0.0019"/>
    <axis xyz="0 0 1"/>
    <dynamics damping="0.0" friction="0.0"/>
  </joint>
  <link name="roller_RB_3_link">
    <visual>
      <origin rpy="0 0 0" xyz="0 0 0"/>
      <geometry>
        <mesh filename="package://engineer_description/meshes/roller.STL"/>
      </geometry>
      <material name="gray">
        <color rgba="0.5 0.5 0.5 1.0"/>
      </material>
    </visual>
    <collision>
      <origin rpy="0 0 0" xyz="0 0 0"/>
      <geometry>
        <mesh filename="package://engineer_description/meshes/roller.STL"/>
      </geometry>
    </collision>
    <inertial>
      <origin rpy="0 0 0" xyz="0 0 0"/>
      <mass value="0.008738"/>
      <inertia ixx="0.000001" ixy="0" ixz="0" iyy="0.000001" iyz="0" izz="0.000001"/>
    </inertial>
  </link>
  <joint name="roller_RB_4_joint" type="continuous">
    <parent link="wheel_RB"/>
    <child link="roller_RB_4_link"/>
    <origin rpy="-0.7854 0 1.284198" xyz="0.018928381812282655 0.06422672273603056 0.0019"/>
    <axis xyz="0 0 1"/>
    <dynamics damping="0.0" friction="0.0"/>
  </joint>
  <link name="roller_RB_4_link">
    <visual>
      <origin rpy="0 0 0" xyz="0 0 0"/>
      <geometry>
        <mesh filename="package://engineer_description/meshes/roller.STL"/>
      </geometry>
      <material name="gray">
        <color rgba="0.5 0.5 0.5 1.0"/>
      </material>
    </visual>
    <collision>
      <origin rpy="0 0 0" xyz="0 0 0"/>
      <geometry>
        <mesh filename="package://engineer_description/meshes/roller.STL"/>
      </geometry>
    </collision>
    <inertial>
      <origin rpy="0 0 0" xyz="0 0 0"/>
      <mass value="0.008738"/>
      <inertia ixx="0.000001" ixy="0" ixz="0" iyy="0.000001" iyz="0" izz="0.000001"/>
    </inertial>
  </link>
  <joint name="roller_RB_5_joint" type="continuous">
    <parent link="wheel_RB"/>
    <child link="roller_RB_5_link"/>
    <origin rpy="-0.7854 0 1.676897" xyz="-0.007090952726648328 0.06658133327645922 0.0019"/>
    <axis xyz="0 0 1"/>
    <dynamics damping="0.0" friction="0.0"/>
  </joint>
  <link name="roller_RB_5_link">
    <visual>
      <origin rpy="0 0 0" xyz="0 0 0"/>
      <geometry>
        <mesh filename="package://engineer_description/meshes/roller.STL"/>
      </geometry>
      <material name="gray">
        <color rgba="0.5 0.5 0.5 1.0"/>
      </material>
    </visual>
    <collision>
      <origin rpy="0 0 0" xyz="0 0 0"/>
      <geometry>
        <mesh filename="package://engineer_description/meshes/roller.STL"/>
      </geometry>
    </collision>
    <inertial>
      <origin rpy="0 0 0" xyz="0 0 0"/>
      <mass value="0.008738"/>
      <inertia ixx="0.000001" ixy="0" ixz="0" iyy="0.000001" iyz="0" izz="0.000001"/>
    </inertial>
  </link>
  <joint name="roller_RB_6_joint" type="continuous">
    <parent link="wheel_RB"/>
    <child link="roller_RB_6_link"/>
    <origin rpy="-0.7854 0 2.069596" xyz="-0.032030754435987296 0.058799543550132914 0.0019"/>
    <axis xyz="0 0 1"/>
    <dynamics damping="0.0" friction="0.0"/>
  </joint>
  <link name="roller_RB_6_link">
    <visual>
      <origin rpy="0 0 0" xyz="0 0 0"/>
      <geometry>
        <mesh filename="package://engineer_description/meshes/roller.STL"/>
      </geometry>
      <material name="gray">
        <color rgba="0.5 0.5 0.5 1.0"/>
      </material>
    </visual>
    <collision>
      <origin rpy="0 0 0" xyz="0 0 0"/>
      <geometry>
        <mesh filename="package://engineer_description/meshes/roller.STL"/>
      </geometry>
    </collision>
    <inertial>
      <origin rpy="0 0 0" xyz="0 0 0"/>
      <mass value="0.008738"/>
      <inertia ixx="0.000001" ixy="0" ixz="0" iyy="0.000001" iyz="0" izz="0.000001"/>
    </inertial>
  </link>
  <joint name="roller_RB_7_joint" type="continuous">
    <parent link="wheel_RB"/>
    <child link="roller_RB_7_link"/>
    <origin rpy="-0.7854 0 2.462295" xyz="-0.05209416614482594 0.042066060014193954 0.0019"/>
    <axis xyz="0 0 1"/>
    <dynamics damping="0.0" friction="0.0"/>
  </joint>
  <link name="roller_RB_7_link">
    <visual>
      <origin rpy="0 0 0" xyz="0 0 0"/>
      <geometry>
        <mesh filename="package://engineer_description/meshes/roller.STL"/>
      </geometry>
      <material name="gray">
        <color rgba="0.5 0.5 0.5 1.0"/>
      </material>
    </visual>
    <collision>
      <origin rpy="0 0 0" xyz="0 0 0"/>
      <geometry>
        <mesh filename="package://engineer_description/meshes/roller.STL"/>
      </geometry>
    </collision>
    <inertial>
      <origin rpy="0 0 0" xyz="0 0 0"/>
      <mass value="0.008738"/>
      <inertia ixx="0.000001" ixy="0" ixz="0" iyy="0.000001" iyz="0" izz="0.000001"/>
    </inertial>
  </link>
  <joint name="roller_RB_8_joint" type="continuous">
    <parent link="wheel_RB"/>
    <child link="roller_RB_8_link"/>
    <origin rpy="-0.7854 0 2.854994" xyz="-0.06422671655032855 0.018928402801246857 0.0019"/>
    <axis xyz="0 0 1"/>
    <dynamics damping="0.0" friction="0.0"/>
  </joint>
  <link name="roller_RB_8_link">
    <visual>
      <origin rpy="0 0 0" xyz="0 0 0"/>
      <geometry>
        <mesh filename="package://engineer_description/meshes/roller.STL"/>
      </geometry>
      <material name="gray">
        <color rgba="0.5 0.5 0.5 1.0"/>
      </material>
    </visual>
    <collision>
      <origin rpy="0 0 0" xyz="0 0 0"/>
      <geometry>
        <mesh filename="package://engineer_description/meshes/roller.STL"/>
      </geometry>
    </collision>
    <inertial>
      <origin rpy="0 0 0" xyz="0 0 0"/>
      <mass value="0.008738"/>
      <inertia ixx="0.000001" ixy="0" ixz="0" iyy="0.000001" iyz="0" izz="0.000001"/>
    </inertial>
  </link>
  <joint name="roller_RB_9_joint" type="continuous">
    <parent link="wheel_RB"/>
    <child link="roller_RB_9_link"/>
    <origin rpy="-0.7854 0 3.247694" xyz="-0.06658132850277856 -0.007090997549540072 0.0019"/>
    <axis xyz="0 0 1"/>
    <dynamics damping="0.0" friction="0.0"/>
  </joint>
  <link name="roller_RB_9_link">
    <visual>
      <origin rpy="0 0 0" xyz="0 0 0"/>
      <geometry>
        <mesh filename="package://engineer_description/meshes/roller.STL"/>
      </geometry>
      <material name="gray">
        <color rgba="0.5 0.5 0.5 1.0"/>
      </material>
    </visual>
    <collision>
      <origin rpy="0 0 0" xyz="0 0 0"/>
      <geometry>
        <mesh filename="package://engineer_description/meshes/roller.STL"/>
      </geometry>
    </collision>
    <inertial>
      <origin rpy="0 0 0" xyz="0 0 0"/>
      <mass value="0.008738"/>
      <inertia ixx="0.000001" ixy="0" ixz="0" iyy="0.000001" iyz="0" izz="0.000001"/>
    </inertial>
  </link>
  <joint name="roller_RB_10_joint" type="continuous">
    <parent link="wheel_RB"/>
    <child link="roller_RB_10_link"/>
    <origin rpy="-0.7854 0 3.640393" xyz="-0.058799521986852246 -0.03203079402013282 0.0019"/>
    <axis xyz="0 0 1"/>
    <dynamics damping="0.0" friction="0.0"/>
  </joint>
  <link name="roller_RB_10_link">
    <visual>
      <origin rpy="0 0 0" xyz="0 0 0"/>
      <geometry>
        <mesh filename="package://engineer_description/meshes/roller.STL"/>
      </geometry>
      <material name="gray">
        <color rgba="0.5 0.5 0.5 1.0"/>
      </material>
    </visual>
    <collision>
      <origin rpy="0 0 0" xyz="0 0 0"/>
      <geometry>
        <mesh filename="package://engineer_description/meshes/roller.STL"/>
      </geometry>
    </collision>
    <inertial>
      <origin rpy="0 0 0" xyz="0 0 0"/>
      <mass value="0.008738"/>
      <inertia ixx="0.000001" ixy="0" ixz="0" iyy="0.000001" iyz="0" izz="0.000001"/>
    </inertial>
  </link>
  <joint name="roller_RB_11_joint" type="continuous">
    <parent link="wheel_RB"/>
    <child link="roller_RB_11_link"/>
    <origin rpy="-0.7854 0 4.033092" xyz="-0.04206602494412593 -0.052094194463900415 0.0019"/>
    <axis xyz="0 0 1"/>
    <dynamics damping="0.0" friction="0.0"/>
  </joint>
  <link name="roller_RB_11_link">
    <visual>
      <origin rpy="0 0 0" xyz="0 0 0"/>
      <geometry>
        <mesh filename="package://engineer_description/meshes/roller.STL"/>
      </geometry>
      <material name="gray">
        <color rgba="0.5 0.5 0.5 1.0"/>
      </material>
    </visual>
    <collision>
      <origin rpy="0 0 0" xyz="0 0 0"/>
      <geometry>
        <mesh filename="package://engineer_description/meshes/roller.STL"/>
      </geometry>
    </collision>
    <inertial>
      <origin rpy="0 0 0" xyz="0 0 0"/>
      <mass value="0.008738"/>
      <inertia ixx="0.000001" ixy="0" ixz="0" iyy="0.000001" iyz="0" izz="0.000001"/>
    </inertial>
  </link>
  <joint name="roller_RB_12_joint" type="continuous">
    <parent link="wheel_RB"/>
    <child link="roller_RB_12_link"/>
    <origin rpy="-0.7854 0 4.425791" xyz="-0.0189283595634892 -0.06422672929301136 0.0019"/>
    <axis xyz="0 0 1"/>
    <dynamics damping="0.0" friction="0.0"/>
  </joint>
  <link name="roller_RB_12_link">
    <visual>
      <origin rpy="0 0 0" xyz="0 0 0"/>
      <geometry>
        <mesh filename="package://engineer_description/meshes/roller.STL"/>
      </geometry>
      <material name="gray">
        <color rgba="0.5 0.5 0.5 1.0"/>
      </material>
    </visual>
    <collision>
      <origin rpy="0 0 0" xyz="0 0 0"/>
      <geometry>
        <mesh filename="package://engineer_description/meshes/roller.STL"/>
      </geometry>
    </collision>
    <inertial>
      <origin rpy="0 0 0" xyz="0 0 0"/>
      <mass value="0.008738"/>
      <inertia ixx="0.000001" ixy="0" ixz="0" iyy="0.000001" iyz="0" izz="0.000001"/>
    </inertial>
  </link>
  <joint name="roller_RB_13_joint" type="continuous">
    <parent link="wheel_RB"/>
    <child link="roller_RB_13_link"/>
    <origin rpy="-0.7854 0 4.81849" xyz="0.007090975791101305 -0.06658133082007683 0.0019"/>
    <axis xyz="0 0 1"/>
    <dynamics damping="0.0" friction="0.0"/>
  </joint>
  <link name="roller_RB_13_link">
    <visual>
      <origin rpy="0 0 0" xyz="0 0 0"/>
      <geometry>
        <mesh filename="package://engineer_description/meshes/roller.STL"/>
      </geometry>
      <material name="gray">
        <color rgba="0.5 0.5 0.5 1.0"/>
      </material>
    </visual>
    <collision>
      <origin rpy="0 0 0" xyz="0 0 0"/>
      <geometry>
        <mesh filename="package://engineer_description/meshes/roller.STL"/>
      </geometry>
    </collision>
    <inertial>
      <origin rpy="0 0 0" xyz="0 0 0"/>
      <mass value="0.008738"/>
      <inertia ixx="0.000001" ixy="0" ixz="0" iyy="0.000001" iyz="0" izz="0.000001"/>
    </inertial>
  </link>
  <joint name="roller_RB_14_joint" type="continuous">
    <parent link="wheel_RB"/>
    <child link="roller_RB_14_link"/>
    <origin rpy="-0.7854 0 5.211189" xyz="0.03203077480474741 -0.05879953245434912 0.0019"/>
    <axis xyz="0 0 1"/>
    <dynamics damping="0.0" friction="0.0"/>
  </joint>
  <link name="roller_RB_14_link">
    <visual>
      <origin rpy="0 0 0" xyz="0 0 0"/>
      <geometry>
        <mesh filename="package://engineer_description/meshes/roller.STL"/>
      </geometry>
      <material name="gray">
        <color rgba="0.5 0.5 0.5 1.0"/>
      </material>
    </visual>
    <collision>
      <origin rpy="0 0 0" xyz="0 0 0"/>
      <geometry>
        <mesh filename="package://engineer_description/meshes/roller.STL"/>
      </geometry>
    </collision>
    <inertial>
      <origin rpy="0 0 0" xyz="0 0 0"/>
      <mass value="0.008738"/>
      <inertia ixx="0.000001" ixy="0" ixz="0" iyy="0.000001" iyz="0" izz="0.000001"/>
    </inertial>
  </link>
  <joint name="roller_RB_15_joint" type="continuous">
    <parent link="wheel_RB"/>
    <child link="roller_RB_15_link"/>
    <origin rpy="-0.7854 0 5.603888" xyz="0.052094180716935376 -0.04206604196824054 0.0019"/>
    <axis xyz="0 0 1"/>
    <dynamics damping="0.0" friction="0.0"/>
  </joint>
  <link name="roller_RB_15_link">
    <visual>
      <origin rpy="0 0 0" xyz="0 0 0"/>
      <geometry>
        <mesh filename="package://engineer_description/meshes/roller.STL"/>
      </geometry>
      <material name="gray">
        <color rgba="0.5 0.5 0.5 1.0"/>
      </material>
    </visual>
    <collision>
      <origin rpy="0 0 0" xyz="0 0 0"/>
      <geometry>
        <mesh filename="package://engineer_description/meshes/roller.STL"/>
      </geometry>
    </collision>
    <inertial>
      <origin rpy="0 0 0" xyz="0 0 0"/>
      <mass value="0.008738"/>
      <inertia ixx="0.000001" ixy="0" ixz="0" iyy="0.000001" iyz="0" izz="0.000001"/>
    </inertial>
  </link>
  <joint name="roller_RB_16_joint" type="continuous">
    <parent link="wheel_RB"/>
    <child link="roller_RB_16_link"/>
    <origin rpy="-0.7854 0 5.996587" xyz="0.06422672310731661 -0.01892838055245557 0.0019"/>
    <axis xyz="0 0 1"/>
    <dynamics damping="0.0" friction="0.0"/>
  </joint>
  <link name="roller_RB_16_link">
    <visual>
      <origin rpy="0 0 0" xyz="0 0 0"/>
      <geometry>
        <mesh filename="package://engineer_description/meshes/roller.STL"/>
      </geometry>
      <material name="gray">
        <color rgba="0.5 0.5 0.5 1.0"/>
      </material>
    </visual>
    <collision>
      <origin rpy="0 0 0" xyz="0 0 0"/>
      <geometry>
        <mesh filename="package://engineer_description/meshes/roller.STL"/>
      </geometry>
    </collision>
    <inertial>
      <origin rpy="0 0 0" xyz="0 0 0"/>
      <mass value="0.008738"/>
      <inertia ixx="0.000001" ixy="0" ixz="0" iyy="0.000001" iyz="0" izz="0.000001"/>
    </inertial>
  </link>
  <joint name="LB_joint" type="continuous">
    <parent link="base_link"/>
    <child link="wheel_LB"/>
    <origin rpy="-1.5708 0 0" xyz="-0.20286 0.2023 -0.012411"/>
    <axis xyz="0 0 1"/>
    <!-- <dynamics damping="3.0" friction="5.0"/> -->
  </joint>
  <link name="wheel_LB">
    <visual>
      <origin rpy="0 0 0" xyz="0 0 0"/>
      <geometry>
        <mesh filename="package://engineer_description/meshes/left-threaded_mecanum_wheel_wheel.STL"/>
      </geometry>
      <material name="white">
        <color rgba="1.0 1.0 1.0 1.0"/>
      </material>
    </visual>
    <collision>
      <origin rpy="0 0 0" xyz="0 0 0"/>
      <geometry>
        <mesh filename="package://engineer_description/meshes/left-threaded_mecanum_wheel_wheel.STL"/>
      </geometry>
    </collision>
    <inertial>
      <origin rpy="0 0 0" xyz="0 0 0"/>
      <mass value="0.007056"/>
      <inertia ixx="0.000017" ixy="0" ixz="0" iyy="0.000017" iyz="0" izz="0.000033"/>
    </inertial>
  </link>
  <joint name="roller_LB_1_joint" type="continuous">
    <parent link="wheel_LB"/>
    <child link="roller_LB_1_link"/>
    <origin rpy="0.7854 0 0.106101" xyz="0.0665813309591685 0.007090974485087869 -0.0019"/>
    <axis xyz="0 0 1"/>
    <dynamics damping="0.0" friction="0.0"/>
  </joint>
  <link name="roller_LB_1_link">
    <visual>
      <origin rpy="0 0 0" xyz="0 0 0"/>
      <geometry>
        <mesh filename="package://engineer_description/meshes/roller.STL"/>
      </geometry>
      <material name="gray">
        <color rgba="0.5 0.5 0.5 1.0"/>
      </material>
    </visual>
    <collision>
      <origin rpy="0 0 0" xyz="0 0 0"/>
      <geometry>
        <mesh filename="package://engineer_description/meshes/roller.STL"/>
      </geometry>
    </collision>
    <inertial>
      <origin rpy="0 0 0" xyz="0 0 0"/>
      <mass value="0.008738"/>
      <inertia ixx="0.000001" ixy="0" ixz="0" iyy="0.000001" iyz="0" izz="0.000001"/>
    </inertial>
  </link>
  <joint name="roller_LB_2_joint" type="continuous">
    <parent link="wheel_LB"/>
    <child link="roller_LB_2_link"/>
    <origin rpy="0.7854 0 0.4988" xyz="0.05879953308264269 0.03203077365137633 -0.0019"/>
    <axis xyz="0 0 1"/>
    <dynamics damping="0.0" friction="0.0"/>
  </joint>
  <link name="roller_LB_2_link">
    <visual>
      <origin rpy="0 0 0" xyz="0 0 0"/>
      <geometry>
        <mesh filename="package://engineer_description/meshes/roller.STL"/>
      </geometry>
      <material name="gray">
        <color rgba="0.5 0.5 0.5 1.0"/>
      </material>
    </visual>
    <collision>
      <origin rpy="0 0 0" xyz="0 0 0"/>
      <geometry>
        <mesh filename="package://engineer_description/meshes/roller.STL"/>
      </geometry>
    </collision>
    <inertial>
      <origin rpy="0 0 0" xyz="0 0 0"/>
      <mass value="0.008738"/>
      <inertia ixx="0.000001" ixy="0" ixz="0" iyy="0.000001" iyz="0" izz="0.000001"/>
    </inertial>
  </link>
  <joint name="roller_LB_3_joint" type="continuous">
    <parent link="wheel_LB"/>
    <child link="roller_LB_3_link"/>
    <origin rpy="0.7854 0 0.891499" xyz="0.04206604299008407 0.0520941798917969 -0.0019"/>
    <axis xyz="0 0 1"/>
    <dynamics damping="0.0" friction="0.0"/>
  </joint>
  <link name="roller_LB_3_link">
    <visual>
      <origin rpy="0 0 0" xyz="0 0 0"/>
      <geometry>
        <mesh filename="package://engineer_description/meshes/roller.STL"/>
      </geometry>
      <material name="gray">
        <color rgba="0.5 0.5 0.5 1.0"/>
      </material>
    </visual>
    <collision>
      <origin rpy="0 0 0" xyz="0 0 0"/>
      <geometry>
        <mesh filename="package://engineer_description/meshes/roller.STL"/>
      </geometry>
    </collision>
    <inertial>
      <origin rpy="0 0 0" xyz="0 0 0"/>
      <mass value="0.008738"/>
      <inertia ixx="0.000001" ixy="0" ixz="0" iyy="0.000001" iyz="0" izz="0.000001"/>
    </inertial>
  </link>
  <joint name="roller_LB_4_joint" type="continuous">
    <parent link="wheel_LB"/>
    <child link="roller_LB_4_link"/>
    <origin rpy="0.7854 0 1.284198" xyz="0.018928381812282655 0.06422672273603056 -0.0019"/>
    <axis xyz="0 0 1"/>
    <dynamics damping="0.0" friction="0.0"/>
  </joint>
  <link name="roller_LB_4_link">
    <visual>
      <origin rpy="0 0 0" xyz="0 0 0"/>
      <geometry>
        <mesh filename="package://engineer_description/meshes/roller.STL"/>
      </geometry>
      <material name="gray">
        <color rgba="0.5 0.5 0.5 1.0"/>
      </material>
    </visual>
    <collision>
      <origin rpy="0 0 0" xyz="0 0 0"/>
      <geometry>
        <mesh filename="package://engineer_description/meshes/roller.STL"/>
      </geometry>
    </collision>
    <inertial>
      <origin rpy="0 0 0" xyz="0 0 0"/>
      <mass value="0.008738"/>
      <inertia ixx="0.000001" ixy="0" ixz="0" iyy="0.000001" iyz="0" izz="0.000001"/>
    </inertial>
  </link>
  <joint name="roller_LB_5_joint" type="continuous">
    <parent link="wheel_LB"/>
    <child link="roller_LB_5_link"/>
    <origin rpy="0.7854 0 1.676897" xyz="-0.007090952726648328 0.06658133327645922 -0.0019"/>
    <axis xyz="0 0 1"/>
    <dynamics damping="0.0" friction="0.0"/>
  </joint>
  <link name="roller_LB_5_link">
    <visual>
      <origin rpy="0 0 0" xyz="0 0 0"/>
      <geometry>
        <mesh filename="package://engineer_description/meshes/roller.STL"/>
      </geometry>
      <material name="gray">
        <color rgba="0.5 0.5 0.5 1.0"/>
      </material>
    </visual>
    <collision>
      <origin rpy="0 0 0" xyz="0 0 0"/>
      <geometry>
        <mesh filename="package://engineer_description/meshes/roller.STL"/>
      </geometry>
    </collision>
    <inertial>
      <origin rpy="0 0 0" xyz="0 0 0"/>
      <mass value="0.008738"/>
      <inertia ixx="0.000001" ixy="0" ixz="0" iyy="0.000001" iyz="0" izz="0.000001"/>
    </inertial>
  </link>
  <joint name="roller_LB_6_joint" type="continuous">
    <parent link="wheel_LB"/>
    <child link="roller_LB_6_link"/>
    <origin rpy="0.7854 0 2.069596" xyz="-0.032030754435987296 0.058799543550132914 -0.0019"/>
    <axis xyz="0 0 1"/>
    <dynamics damping="0.0" friction="0.0"/>
  </joint>
  <link name="roller_LB_6_link">
    <visual>
      <origin rpy="0 0 0" xyz="0 0 0"/>
      <geometry>
        <mesh filename="package://engineer_description/meshes/roller.STL"/>
      </geometry>
      <material name="gray">
        <color rgba="0.5 0.5 0.5 1.0"/>
      </material>
    </visual>
    <collision>
      <origin rpy="0 0 0" xyz="0 0 0"/>
      <geometry>
        <mesh filename="package://engineer_description/meshes/roller.STL"/>
      </geometry>
    </collision>
    <inertial>
      <origin rpy="0 0 0" xyz="0 0 0"/>
      <mass value="0.008738"/>
      <inertia ixx="0.000001" ixy="0" ixz="0" iyy="0.000001" iyz="0" izz="0.000001"/>
    </inertial>
  </link>
  <joint name="roller_LB_7_joint" type="continuous">
    <parent link="wheel_LB"/>
    <child link="roller_LB_7_link"/>
    <origin rpy="0.7854 0 2.462295" xyz="-0.05209416614482594 0.042066060014193954 -0.0019"/>
    <axis xyz="0 0 1"/>
    <dynamics damping="0.0" friction="0.0"/>
  </joint>
  <link name="roller_LB_7_link">
    <visual>
      <origin rpy="0 0 0" xyz="0 0 0"/>
      <geometry>
        <mesh filename="package://engineer_description/meshes/roller.STL"/>
      </geometry>
      <material name="gray">
        <color rgba="0.5 0.5 0.5 1.0"/>
      </material>
    </visual>
    <collision>
      <origin rpy="0 0 0" xyz="0 0 0"/>
      <geometry>
        <mesh filename="package://engineer_description/meshes/roller.STL"/>
      </geometry>
    </collision>
    <inertial>
      <origin rpy="0 0 0" xyz="0 0 0"/>
      <mass value="0.008738"/>
      <inertia ixx="0.000001" ixy="0" ixz="0" iyy="0.000001" iyz="0" izz="0.000001"/>
    </inertial>
  </link>
  <joint name="roller_LB_8_joint" type="continuous">
    <parent link="wheel_LB"/>
    <child link="roller_LB_8_link"/>
    <origin rpy="0.7854 0 2.854994" xyz="-0.06422671655032855 0.018928402801246857 -0.0019"/>
    <axis xyz="0 0 1"/>
    <dynamics damping="0.0" friction="0.0"/>
  </joint>
  <link name="roller_LB_8_link">
    <visual>
      <origin rpy="0 0 0" xyz="0 0 0"/>
      <geometry>
        <mesh filename="package://engineer_description/meshes/roller.STL"/>
      </geometry>
      <material name="gray">
        <color rgba="0.5 0.5 0.5 1.0"/>
      </material>
    </visual>
    <collision>
      <origin rpy="0 0 0" xyz="0 0 0"/>
      <geometry>
        <mesh filename="package://engineer_description/meshes/roller.STL"/>
      </geometry>
    </collision>
    <inertial>
      <origin rpy="0 0 0" xyz="0 0 0"/>
      <mass value="0.008738"/>
      <inertia ixx="0.000001" ixy="0" ixz="0" iyy="0.000001" iyz="0" izz="0.000001"/>
    </inertial>
  </link>
  <joint name="roller_LB_9_joint" type="continuous">
    <parent link="wheel_LB"/>
    <child link="roller_LB_9_link"/>
    <origin rpy="0.7854 0 3.247694" xyz="-0.06658132850277856 -0.007090997549540072 -0.0019"/>
    <axis xyz="0 0 1"/>
    <dynamics damping="0.0" friction="0.0"/>
  </joint>
  <link name="roller_LB_9_link">
    <visual>
      <origin rpy="0 0 0" xyz="0 0 0"/>
      <geometry>
        <mesh filename="package://engineer_description/meshes/roller.STL"/>
      </geometry>
      <material name="gray">
        <color rgba="0.5 0.5 0.5 1.0"/>
      </material>
    </visual>
    <collision>
      <origin rpy="0 0 0" xyz="0 0 0"/>
      <geometry>
        <mesh filename="package://engineer_description/meshes/roller.STL"/>
      </geometry>
    </collision>
    <inertial>
      <origin rpy="0 0 0" xyz="0 0 0"/>
      <mass value="0.008738"/>
      <inertia ixx="0.000001" ixy="0" ixz="0" iyy="0.000001" iyz="0" izz="0.000001"/>
    </inertial>
  </link>
  <joint name="roller_LB_10_joint" type="continuous">
    <parent link="wheel_LB"/>
    <child link="roller_LB_10_link"/>
    <origin rpy="0.7854 0 3.640393" xyz="-0.058799521986852246 -0.03203079402013282 -0.0019"/>
    <axis xyz="0 0 1"/>
    <dynamics damping="0.0" friction="0.0"/>
  </joint>
  <link name="roller_LB_10_link">
    <visual>
      <origin rpy="0 0 0" xyz="0 0 0"/>
      <geometry>
        <mesh filename="package://engineer_description/meshes/roller.STL"/>
      </geometry>
      <material name="gray">
        <color rgba="0.5 0.5 0.5 1.0"/>
      </material>
    </visual>
    <collision>
      <origin rpy="0 0 0" xyz="0 0 0"/>
      <geometry>
        <mesh filename="package://engineer_description/meshes/roller.STL"/>
      </geometry>
    </collision>
    <inertial>
      <origin rpy="0 0 0" xyz="0 0 0"/>
      <mass value="0.008738"/>
      <inertia ixx="0.000001" ixy="0" ixz="0" iyy="0.000001" iyz="0" izz="0.000001"/>
    </inertial>
  </link>
  <joint name="roller_LB_11_joint" type="continuous">
    <parent link="wheel_LB"/>
    <child link="roller_LB_11_link"/>
    <origin rpy="0.7854 0 4.033092" xyz="-0.04206602494412593 -0.052094194463900415 -0.0019"/>
    <axis xyz="0 0 1"/>
    <dynamics damping="0.0" friction="0.0"/>
  </joint>
  <link name="roller_LB_11_link">
    <visual>
      <origin rpy="0 0 0" xyz="0 0 0"/>
      <geometry>
        <mesh filename="package://engineer_description/meshes/roller.STL"/>
      </geometry>
      <material name="gray">
        <color rgba="0.5 0.5 0.5 1.0"/>
      </material>
    </visual>
    <collision>
      <origin rpy="0 0 0" xyz="0 0 0"/>
      <geometry>
        <mesh filename="package://engineer_description/meshes/roller.STL"/>
      </geometry>
    </collision>
    <inertial>
      <origin rpy="0 0 0" xyz="0 0 0"/>
      <mass value="0.008738"/>
      <inertia ixx="0.000001" ixy="0" ixz="0" iyy="0.000001" iyz="0" izz="0.000001"/>
    </inertial>
  </link>
  <joint name="roller_LB_12_joint" type="continuous">
    <parent link="wheel_LB"/>
    <child link="roller_LB_12_link"/>
    <origin rpy="0.7854 0 4.425791" xyz="-0.0189283595634892 -0.06422672929301136 -0.0019"/>
    <axis xyz="0 0 1"/>
    <dynamics damping="0.0" friction="0.0"/>
  </joint>
  <link name="roller_LB_12_link">
    <visual>
      <origin rpy="0 0 0" xyz="0 0 0"/>
      <geometry>
        <mesh filename="package://engineer_description/meshes/roller.STL"/>
      </geometry>
      <material name="gray">
        <color rgba="0.5 0.5 0.5 1.0"/>
      </material>
    </visual>
    <collision>
      <origin rpy="0 0 0" xyz="0 0 0"/>
      <geometry>
        <mesh filename="package://engineer_description/meshes/roller.STL"/>
      </geometry>
    </collision>
    <inertial>
      <origin rpy="0 0 0" xyz="0 0 0"/>
      <mass value="0.008738"/>
      <inertia ixx="0.000001" ixy="0" ixz="0" iyy="0.000001" iyz="0" izz="0.000001"/>
    </inertial>
  </link>
  <joint name="roller_LB_13_joint" type="continuous">
    <parent link="wheel_LB"/>
    <child link="roller_LB_13_link"/>
    <origin rpy="0.7854 0 4.81849" xyz="0.007090975791101305 -0.06658133082007683 -0.0019"/>
    <axis xyz="0 0 1"/>
    <dynamics damping="0.0" friction="0.0"/>
  </joint>
  <link name="roller_LB_13_link">
    <visual>
      <origin rpy="0 0 0" xyz="0 0 0"/>
      <geometry>
        <mesh filename="package://engineer_description/meshes/roller.STL"/>
      </geometry>
      <material name="gray">
        <color rgba="0.5 0.5 0.5 1.0"/>
      </material>
    </visual>
    <collision>
      <origin rpy="0 0 0" xyz="0 0 0"/>
      <geometry>
        <mesh filename="package://engineer_description/meshes/roller.STL"/>
      </geometry>
    </collision>
    <inertial>
      <origin rpy="0 0 0" xyz="0 0 0"/>
      <mass value="0.008738"/>
      <inertia ixx="0.000001" ixy="0" ixz="0" iyy="0.000001" iyz="0" izz="0.000001"/>
    </inertial>
  </link>
  <joint name="roller_LB_14_joint" type="continuous">
    <parent link="wheel_LB"/>
    <child link="roller_LB_14_link"/>
    <origin rpy="0.7854 0 5.211189" xyz="0.03203077480474741 -0.05879953245434912 -0.0019"/>
    <axis xyz="0 0 1"/>
    <dynamics damping="0.0" friction="0.0"/>
  </joint>
  <link name="roller_LB_14_link">
    <visual>
      <origin rpy="0 0 0" xyz="0 0 0"/>
      <geometry>
        <mesh filename="package://engineer_description/meshes/roller.STL"/>
      </geometry>
      <material name="gray">
        <color rgba="0.5 0.5 0.5 1.0"/>
      </material>
    </visual>
    <collision>
      <origin rpy="0 0 0" xyz="0 0 0"/>
      <geometry>
        <mesh filename="package://engineer_description/meshes/roller.STL"/>
      </geometry>
    </collision>
    <inertial>
      <origin rpy="0 0 0" xyz="0 0 0"/>
      <mass value="0.008738"/>
      <inertia ixx="0.000001" ixy="0" ixz="0" iyy="0.000001" iyz="0" izz="0.000001"/>
    </inertial>
  </link>
  <joint name="roller_LB_15_joint" type="continuous">
    <parent link="wheel_LB"/>
    <child link="roller_LB_15_link"/>
    <origin rpy="0.7854 0 5.603888" xyz="0.052094180716935376 -0.04206604196824054 -0.0019"/>
    <axis xyz="0 0 1"/>
    <dynamics damping="0.0" friction="0.0"/>
  </joint>
  <link name="roller_LB_15_link">
    <visual>
      <origin rpy="0 0 0" xyz="0 0 0"/>
      <geometry>
        <mesh filename="package://engineer_description/meshes/roller.STL"/>
      </geometry>
      <material name="gray">
        <color rgba="0.5 0.5 0.5 1.0"/>
      </material>
    </visual>
    <collision>
      <origin rpy="0 0 0" xyz="0 0 0"/>
      <geometry>
        <mesh filename="package://engineer_description/meshes/roller.STL"/>
      </geometry>
    </collision>
    <inertial>
      <origin rpy="0 0 0" xyz="0 0 0"/>
      <mass value="0.008738"/>
      <inertia ixx="0.000001" ixy="0" ixz="0" iyy="0.000001" iyz="0" izz="0.000001"/>
    </inertial>
  </link>
  <joint name="roller_LB_16_joint" type="continuous">
    <parent link="wheel_LB"/>
    <child link="roller_LB_16_link"/>
    <origin rpy="0.7854 0 5.996587" xyz="0.06422672310731661 -0.01892838055245557 -0.0019"/>
    <axis xyz="0 0 1"/>
    <dynamics damping="0.0" friction="0.0"/>
  </joint>
  <link name="roller_LB_16_link">
    <visual>
      <origin rpy="0 0 0" xyz="0 0 0"/>
      <geometry>
        <mesh filename="package://engineer_description/meshes/roller.STL"/>
      </geometry>
      <material name="gray">
        <color rgba="0.5 0.5 0.5 1.0"/>
      </material>
    </visual>
    <collision>
      <origin rpy="0 0 0" xyz="0 0 0"/>
      <geometry>
        <mesh filename="package://engineer_description/meshes/roller.STL"/>
      </geometry>
    </collision>
    <inertial>
      <origin rpy="0 0 0" xyz="0 0 0"/>
      <mass value="0.008738"/>
      <inertia ixx="0.000001" ixy="0" ixz="0" iyy="0.000001" iyz="0" izz="0.000001"/>
    </inertial>
  </link>
  <joint name="link1_joint" type="revolute">
    <parent link="base_link"/>
    <child link="link1"/>
    <origin rpy="0 0 0" xyz="0 0 0.0715"/>
    <axis xyz="0 0 1"/>
    <limit effort="0" lower="-0.7854" upper="0.7854" velocity="0"/>
  </joint>
  <link name="link1">
    <visual>
      <origin rpy="0 0 0" xyz="0 0 0"/>
      <geometry>
        <mesh filename="package://engineer_description/meshes/link1.STL"/>
      </geometry>
      <material name="white">
        <color rgba="1.0 1.0 1.0 1.0"/>
      </material>
    </visual>
    <collision>
      <origin rpy="0 0 0" xyz="0 0 0"/>
      <geometry>
        <mesh filename="package://engineer_description/meshes/link1.STL"/>
      </geometry>
    </collision>
    <inertial>
      <origin rpy="0 0 0" xyz="-0.000941 0.005367 0.0733"/>
      <mass value="1.17054"/>
      <inertia ixx="0.005224" ixy="1e-06" ixz="3.6e-05" iyy="0.005534" iyz="-0.000205" izz="0.004345"/>
    </inertial>
  </link>
  <joint name="link2_joint" type="revolute">
    <parent link="link1"/>
    <child link="link2"/>
    <origin rpy="-1.5708 -1.0472 0" xyz="0 0 0.118"/>
    <axis xyz="0 0 1"/>
    <limit effort="0" lower="1e-06" upper="2.0944" velocity="0"/>
  </joint>
  <link name="link2">
    <visual>
      <origin rpy="0 0 0" xyz="0 0 0"/>
      <geometry>
        <mesh filename="package://engineer_description/meshes/link2.STL"/>
      </geometry>
      <material name="white">
        <color rgba="1.0 1.0 1.0 1.0"/>
      </material>
    </visual>
    <collision>
      <origin rpy="0 0 0" xyz="0 0 0"/>
      <geometry>
        <mesh filename="package://engineer_description/meshes/link2.STL"/>
      </geometry>
    </collision>
    <inertial>
      <origin rpy="0 0 0" xyz="0.001243 -0.205517 -0.004229"/>
      <mass value="1.37833"/>
      <inertia ixx="0.026143" ixy="-0.00183" ixz="0.000127" iyy="0.002503" iyz="5e-05" izz="0.02504"/>
    </inertial>
  </link>
  <joint name="link3_joint" type="revolute">
    <parent link="link2"/>
    <child link="link3"/>
    <origin rpy="0 0 1.0472" xyz="0 -0.36 0"/>
    <axis xyz="0 0 1"/>
    <limit effort="0" lower="-2.618" upper="1e-06" velocity="0"/>
  </joint>
  <link name="link3">
    <visual>
      <origin rpy="0 0 0" xyz="0 0 0"/>
      <geometry>
        <mesh filename="package://engineer_description/meshes/link3.STL"/>
      </geometry>
      <material name="white">
        <color rgba="1.0 1.0 1.0 1.0"/>
      </material>
    </visual>
    <collision>
      <origin rpy="0 0 0" xyz="0 0 0"/>
      <geometry>
        <mesh filename="package://engineer_description/meshes/link3.STL"/>
      </geometry>
    </collision>
    <inertial>
      <origin rpy="0 0 0" xyz="0.124814 -0.008956 -0.000451"/>
      <mass value="1.58588"/>
      <inertia ixx="0.001743" ixy="5e-06" ixz="-9.8e-05" iyy="0.0044" iyz="1.8e-05" izz="0.004198"/>
    </inertial>
  </link>
  <joint name="link4_joint" type="revolute">
    <parent link="link3"/>
    <child link="link4"/>
    <origin rpy="1.5708 0 0" xyz="0.152 -0.003 0"/>
    <axis xyz="0 0 1"/>
    <limit effort="0" lower="-0.5" upper="0.5" velocity="0"/>
  </joint>
  <link name="link4">
    <visual>
      <origin rpy="0 0 0" xyz="0 0 0"/>
      <geometry>
        <mesh filename="package://engineer_description/meshes/link4.STL"/>
      </geometry>
      <material name="white">
        <color rgba="1.0 1.0 1.0 1.0"/>
      </material>
    </visual>
    <collision>
      <origin rpy="0 0 0" xyz="0 0 0"/>
      <geometry>
        <mesh filename="package://engineer_description/meshes/link4.STL"/>
      </geometry>
    </collision>
    <inertial>
      <origin rpy="0 0 0" xyz="0.036944 -0.000149 0.001115"/>
      <mass value="0.139812"/>
      <inertia ixx="0.000232" ixy="0" ixz="7e-06" iyy="0.000195" iyz="0" izz="0.000157"/>
    </inertial>
  </link>
  <joint name="link5_joint" type="revolute">
    <parent link="link4"/>
    <child link="link5"/>
    <origin rpy="0 1.5708 0" xyz="0.0756 0 0"/>
    <axis xyz="0 0 1"/>
    <limit effort="0" lower="-1.5709" upper="1.5709" velocity="0"/>
  </joint>
  <link name="link5">
    <visual>
      <origin rpy="0 0 0" xyz="0 0 0"/>
      <geometry>
        <mesh filename="package://engineer_description/meshes/link5.STL"/>
      </geometry>
      <material name="white">
        <color rgba="1.0 1.0 1.0 1.0"/>
      </material>
    </visual>
    <collision>
      <origin rpy="0 0 0" xyz="0 0 0"/>
      <geometry>
        <mesh filename="package://engineer_description/meshes/link5.STL"/>
      </geometry>
    </collision>
    <inertial>
      <origin rpy="0 0 0" xyz="6e-06 1.1e-05 0.037589"/>
      <mass value="0.528241"/>
      <inertia ixx="0.001034" ixy="9e-06" ixz="-1e-06" iyy="0.000977" iyz="-1e-06" izz="0.000568"/>
    </inertial>
  </link>
  <joint name="link6_joint" type="revolute">
    <parent link="link5"/>
    <child link="link6"/>
    <origin rpy="-1.6081 -1.5708 0.037258" xyz="0 0 0.1614"/>
    <axis xyz="0 0 1"/>
    <limit effort="0" lower="-1.8" upper="1.8" velocity="0"/>
  </joint>
  <link name="link6">
    <visual>
      <origin rpy="0 0 0" xyz="0 0 0"/>
      <geometry>
        <mesh filename="package://engineer_description/meshes/link6.STL"/>
      </geometry>
      <material name="white">
        <color rgba="1.0 1.0 1.0 1.0"/>
      </material>
    </visual>
    <collision>
      <origin rpy="0 0 0" xyz="0 0 0"/>
      <geometry>
        <mesh filename="package://engineer_description/meshes/link6.STL"/>
      </geometry>
    </collision>
    <inertial>
      <origin rpy="0 0 0" xyz="0.005373 -0.001981 2e-06"/>
      <mass value="0.159991"/>
      <inertia ixx="0.000102" ixy="-3e-06" ixz="0" iyy="0.000146" iyz="0" izz="8e-05"/>
    </inertial>
  </link>
  <joint name="link7_joint" type="revolute">
    <parent link="link6"/>
    <child link="link7"/>
    <origin rpy="1.5708 0 1.5708" xyz="0.04955 0 0"/>
    <axis xyz="0 0 1"/>
    <limit effort="0" lower="-6.28" upper="6.28" velocity="0"/>
  </joint>
  <link name="link7">
    <visual>
      <origin rpy="0 0 0" xyz="0 0 0"/>
      <geometry>
        <mesh filename="package://engineer_description/meshes/link7.STL"/>
      </geometry>
      <material name="white">
        <color rgba="1.0 1.0 1.0 1.0"/>
      </material>
    </visual>
    <collision>
      <origin rpy="0 0 0" xyz="0 0 0"/>
      <geometry>
        <mesh filename="package://engineer_description/meshes/link7.STL"/>
      </geometry>
    </collision>
    <inertial>
      <origin rpy="0 0 0" xyz="0 0 0.006021"/>
      <mass value="0.007071"/>
      <inertia ixx="1e-06" ixy="0" ixz="0" iyy="1e-06" iyz="0" izz="1e-06"/>
    </inertial>
  </link>
  <joint name="left_z_joint" type="prismatic">
    <parent link="base_link"/>
    <child link="left_z_link"/>
    <origin rpy="0 0 0" xyz="0.0633 0.2075 0.20311"/>
    <axis xyz="0 0 1"/>
    <limit effort="0" lower="1e-06" upper="0.08969" velocity="0"/>
  </joint>
  <link name="left_z_link">
    <visual>
      <origin rpy="0 0 0" xyz="0 0 0"/>
      <geometry>
        <mesh filename="package://engineer_description/meshes/left_z_link.STL"/>
      </geometry>
      <material name="white">
        <color rgba="1.0 1.0 1.0 1.0"/>
      </material>
    </visual>
    <collision>
      <origin rpy="0 0 0" xyz="0 0 0"/>
      <geometry>
        <mesh filename="package://engineer_description/meshes/left_z_link.STL"/>
      </geometry>
    </collision>
    <inertial>
      <origin rpy="0 0 0" xyz="-0.058037 0.007699 0.062634"/>
      <mass value="2.06473"/>
      <inertia ixx="0.007718" ixy="0.000177" ixz="0.000195" iyy="0.028724" iyz="1e-05" izz="0.024449"/>
    </inertial>
  </link>
  <joint name="left_x_joint" type="prismatic">
    <parent link="left_z_link"/>
    <child link="left_x_link"/>
    <origin rpy="0 0 0" xyz="-0.221 0.0325 0.144"/>
    <axis xyz="1 0 0"/>
    <limit effort="0" lower="1e-06" upper="0.3096" velocity="0"/>
  </joint>
  <link name="left_x_link">
    <visual>
      <origin rpy="0 0 0" xyz="0 0 0"/>
      <geometry>
        <mesh filename="package://engineer_description/meshes/left_x_link.STL"/>
      </geometry>
      <material name="white">
        <color rgba="1.0 1.0 1.0 1.0"/>
      </material>
    </visual>
    <collision>
      <origin rpy="0 0 0" xyz="0 0 0"/>
      <geometry>
        <mesh filename="package://engineer_description/meshes/left_x_link.STL"/>
      </geometry>
    </collision>
    <inertial>
      <origin rpy="0 0 0" xyz="0.161562 -0.055708 -0.018456"/>
      <mass value="0.814767"/>
      <inertia ixx="0.000786" ixy="0.0003" ixz="0.001781" iyy="0.026338" iyz="-2.6e-05" izz="0.026443"/>
    </inertial>
  </link>
  <joint name="left_yaw_joint" type="revolute">
    <parent link="left_x_link"/>
    <child link="left_yaw_link"/>
    <origin rpy="0 0 0" xyz="0.4435 -0.0583 -0.0075"/>
    <axis xyz="0 0 1"/>
    <limit effort="0" lower="-2.0944" upper="2.0944" velocity="0"/>
  </joint>
  <link name="left_yaw_link">
    <visual>
      <origin rpy="0 0 0" xyz="0 0 0"/>
      <geometry>
        <mesh filename="package://engineer_description/meshes/left_yaw_link.STL"/>
      </geometry>
      <material name="white">
        <color rgba="1.0 1.0 1.0 1.0"/>
      </material>
    </visual>
    <collision>
      <origin rpy="0 0 0" xyz="0 0 0"/>
      <geometry>
        <mesh filename="package://engineer_description/meshes/left_yaw_link.STL"/>
      </geometry>
    </collision>
    <inertial>
      <origin rpy="0 0 0" xyz="0.063197 -2.2e-05 -0.031301"/>
      <mass value="0.06449"/>
      <inertia ixx="6.9e-05" ixy="0" ixz="4.9e-05" iyy="0.000137" iyz="0" izz="8.6e-05"/>
    </inertial>
  </link>
  <joint name="right_z_joint" type="prismatic">
    <parent link="base_link"/>
    <child link="right_z_link"/>
    <origin rpy="0 0 0" xyz="0.0658 -0.2075 0.20311"/>
    <axis xyz="0 0 1"/>
    <limit effort="0" lower="1e-06" upper="0.08969" velocity="0"/>
  </joint>
  <link name="right_z_link">
    <visual>
      <origin rpy="0 0 0" xyz="0 0 0"/>
      <geometry>
        <mesh filename="package://engineer_description/meshes/right_z_link.STL"/>
      </geometry>
      <material name="white">
        <color rgba="1.0 1.0 1.0 1.0"/>
      </material>
    </visual>
    <collision>
      <origin rpy="0 0 0" xyz="0 0 0"/>
      <geometry>
        <mesh filename="package://engineer_description/meshes/right_z_link.STL"/>
      </geometry>
    </collision>
    <inertial>
      <origin rpy="0 0 0" xyz="-0.055178 -0.004026 0.059103"/>
      <mass value="1.69853"/>
      <inertia ixx="0.005215" ixy="-0.000469" ixz="-4.1e-05" iyy="0.024571" iyz="-0.000786" izz="0.021373"/>
    </inertial>
  </link>
  <joint name="right_x_joint" type="prismatic">
    <parent link="right_z_link"/>
    <child link="right_x_link"/>
    <origin rpy="0 0 0" xyz="-0.2481 -0.032 0.144"/>
    <axis xyz="1 0 0"/>
    <limit effort="0" lower="1e-06" upper="0.3096" velocity="0"/>
  </joint>
  <link name="right_x_link">
    <visual>
      <origin rpy="0 0 0" xyz="0 0 0"/>
      <geometry>
        <mesh filename="package://engineer_description/meshes/right_x_link.STL"/>
      </geometry>
      <material name="white">
        <color rgba="1.0 1.0 1.0 1.0"/>
      </material>
    </visual>
    <collision>
      <origin rpy="0 0 0" xyz="0 0 0"/>
      <geometry>
        <mesh filename="package://engineer_description/meshes/right_x_link.STL"/>
      </geometry>
    </collision>
    <inertial>
      <origin rpy="0 0 0" xyz="0.205338 0.052611 -0.020548"/>
      <mass value="0.603922"/>
      <inertia ixx="0.000591" ixy="-0.000686" ixz="0.001355" iyy="0.021109" iyz="6.5e-05" izz="0.021222"/>
    </inertial>
  </link>
  <joint name="right_yaw_joint" type="revolute">
    <parent link="right_x_link"/>
    <child link="right_yaw_link"/>
    <origin rpy="0 0 0.018823" xyz="0.4435 0.0583 -0.0055"/>
    <axis xyz="0 0 1"/>
    <limit effort="0" lower="-2.0944" upper="2.0944" velocity="0"/>
  </joint>
  <link name="right_yaw_link">
    <visual>
      <origin rpy="0 0 0" xyz="0 0 0"/>
      <geometry>
        <mesh filename="package://engineer_description/meshes/right_yaw_link.STL"/>
      </geometry>
      <material name="white">
        <color rgba="1.0 1.0 1.0 1.0"/>
      </material>
    </visual>
    <collision>
      <origin rpy="0 0 0" xyz="0 0 0"/>
      <geometry>
        <mesh filename="package://engineer_description/meshes/right_yaw_link.STL"/>
      </geometry>
    </collision>
    <inertial>
      <origin rpy="0 0 0" xyz="0.063197 2.2e-05 -0.033301"/>
      <mass value="0.06449"/>
      <inertia ixx="6.9e-05" ixy="0" ixz="4.9e-05" iyy="0.000137" iyz="0" izz="8.6e-05"/>
    </inertial>
  </link>
  <joint name="engineer_depth_camera_joint" type="fixed">
    <parent link="link4"/>
    <child link="engineer_depth_camera_link"/>
    <origin rpy="0 0 0" xyz="0 0 0.075"/>
    <axis xyz="0 0 1"/>
  </joint>
  <link name="engineer_depth_camera_link">
    <visual>
      <origin rpy="0 0 0" xyz="0 0 0"/>
      <geometry>
        <cylinder length="0.0002" radius="0.0002"/>
      </geometry>
      <material name="black">
        <color rgba="0.0 0.0 0.0 1.0"/>
      </material>
    </visual>
  </link>
  <joint name="engineer_depth_camera_optical_joint" type="fixed">
    <origin rpy="-1.5707963267948966 0 -1.5707963267948966" xyz="0 0 0"/>
    <parent link="engineer_depth_camera_link"/>
    <child link="engineer_depth_camera_optical_link"/>
  </joint>
  <link name="engineer_depth_camera_optical_link"/>
  <transmission name="LF_trans">
    <type>transmission_interface/SimpleTransmission</type>
    <joint name="LF_joint">
      <hardwareInterface>hardware_interface/VelocityJointInterface</hardwareInterface>
    </joint>
    <actuator name="LF_motor">
      <hardwareInterface>hardware_interface/VelocityJointInterface</hardwareInterface>
      <mechanicalReduction>1</mechanicalReduction>
    </actuator>
  </transmission>
  <transmission name="RF_trans">
    <type>transmission_interface/SimpleTransmission</type>
    <joint name="RF_joint">
      <hardwareInterface>hardware_interface/VelocityJointInterface</hardwareInterface>
    </joint>
    <actuator name="RF_motor">
      <hardwareInterface>hardware_interface/VelocityJointInterface</hardwareInterface>
      <mechanicalReduction>1</mechanicalReduction>
    </actuator>
  </transmission>
  <transmission name="RB_trans">
    <type>transmission_interface/SimpleTransmission</type>
    <joint name="RB_joint">
      <hardwareInterface>hardware_interface/VelocityJointInterface</hardwareInterface>
    </joint>
    <actuator name="RB_motor">
      <hardwareInterface>hardware_interface/VelocityJointInterface</hardwareInterface>
      <mechanicalReduction>1</mechanicalReduction>
    </actuator>
  </transmission>
  <transmission name="LB_trans">
    <type>transmission_interface/SimpleTransmission</type>
    <joint name="LB_joint">
      <hardwareInterface>hardware_interface/VelocityJointInterface</hardwareInterface>
    </joint>
    <actuator name="LB_motor">
      <hardwareInterface>hardware_interface/VelocityJointInterface</hardwareInterface>
      <mechanicalReduction>1</mechanicalReduction>
    </actuator>
  </transmission>
  <gazebo reference="wheel_LF">
    <selfCollide>true</selfCollide>
    <gravity>true</gravity>
    <mu1>50</mu1>
    <mu2>50</mu2>
    <kp>1e50</kp>
    <kd>1e50</kd>
    <material>Gazebo/White</material>
  </gazebo>
  <gazebo reference="wheel_RF">
    <selfCollide>true</selfCollide>
    <gravity>true</gravity>
    <mu1>50</mu1>
    <mu2>50</mu2>
    <kp>1e50</kp>
    <kd>1e50</kd>
    <material>Gazebo/White</material>
  </gazebo>
  <gazebo reference="wheel_RB">
    <selfCollide>true</selfCollide>
    <gravity>true</gravity>
    <mu1>50</mu1>
    <mu2>50</mu2>
    <kp>1e50</kp>
    <kd>1e50</kd>
    <material>Gazebo/White</material>
  </gazebo>
  <gazebo reference="wheel_LB">
    <selfCollide>true</selfCollide>
    <gravity>true</gravity>
    <mu1>50</mu1>
    <mu2>50</mu2>
    <kp>1e50</kp>
    <kd>1e50</kd>
    <material>Gazebo/White</material>
  </gazebo>
  <gazebo reference="roller_LF_1_link">
    <selfCollide>true</selfCollide>
    <gravity>true</gravity>
    <mu1>30</mu1>
    <mu2>30</mu2>
    <kp>1e50</kp>
    <kd>1e50</kd>
    <material>Gazebo/Grey</material>
  </gazebo>
  <gazebo reference="roller_LF_2_link">
    <selfCollide>true</selfCollide>
    <gravity>true</gravity>
    <mu1>30</mu1>
    <mu2>30</mu2>
    <kp>1e50</kp>
    <kd>1e50</kd>
    <material>Gazebo/Grey</material>
  </gazebo>
  <gazebo reference="roller_LF_3_link">
    <selfCollide>true</selfCollide>
    <gravity>true</gravity>
    <mu1>30</mu1>
    <mu2>30</mu2>
    <kp>1e50</kp>
    <kd>1e50</kd>
    <material>Gazebo/Grey</material>
  </gazebo>
  <gazebo reference="roller_LF_4_link">
    <selfCollide>true</selfCollide>
    <gravity>true</gravity>
    <mu1>30</mu1>
    <mu2>30</mu2>
    <kp>1e50</kp>
    <kd>1e50</kd>
    <material>Gazebo/Grey</material>
  </gazebo>
  <gazebo reference="roller_LF_5_link">
    <selfCollide>true</selfCollide>
    <gravity>true</gravity>
    <mu1>30</mu1>
    <mu2>30</mu2>
    <kp>1e50</kp>
    <kd>1e50</kd>
    <material>Gazebo/Grey</material>
  </gazebo>
  <gazebo reference="roller_LF_6_link">
    <selfCollide>true</selfCollide>
    <gravity>true</gravity>
    <mu1>30</mu1>
    <mu2>30</mu2>
    <kp>1e50</kp>
    <kd>1e50</kd>
    <material>Gazebo/Grey</material>
  </gazebo>
  <gazebo reference="roller_LF_7_link">
    <selfCollide>true</selfCollide>
    <gravity>true</gravity>
    <mu1>30</mu1>
    <mu2>30</mu2>
    <kp>1e50</kp>
    <kd>1e50</kd>
    <material>Gazebo/Grey</material>
  </gazebo>
  <gazebo reference="roller_LF_8_link">
    <selfCollide>true</selfCollide>
    <gravity>true</gravity>
    <mu1>30</mu1>
    <mu2>30</mu2>
    <kp>1e50</kp>
    <kd>1e50</kd>
    <material>Gazebo/Grey</material>
  </gazebo>
  <gazebo reference="roller_LF_9_link">
    <selfCollide>true</selfCollide>
    <gravity>true</gravity>
    <mu1>30</mu1>
    <mu2>30</mu2>
    <kp>1e50</kp>
    <kd>1e50</kd>
    <material>Gazebo/Grey</material>
  </gazebo>
  <gazebo reference="roller_LF_10_link">
    <selfCollide>true</selfCollide>
    <gravity>true</gravity>
    <mu1>30</mu1>
    <mu2>30</mu2>
    <kp>1e50</kp>
    <kd>1e50</kd>
    <material>Gazebo/Grey</material>
  </gazebo>
  <gazebo reference="roller_LF_11_link">
    <selfCollide>true</selfCollide>
    <gravity>true</gravity>
    <mu1>30</mu1>
    <mu2>30</mu2>
    <kp>1e50</kp>
    <kd>1e50</kd>
    <material>Gazebo/Grey</material>
  </gazebo>
  <gazebo reference="roller_LF_12_link">
    <selfCollide>true</selfCollide>
    <gravity>true</gravity>
    <mu1>30</mu1>
    <mu2>30</mu2>
    <kp>1e50</kp>
    <kd>1e50</kd>
    <material>Gazebo/Grey</material>
  </gazebo>
  <gazebo reference="roller_LF_13_link">
    <selfCollide>true</selfCollide>
    <gravity>true</gravity>
    <mu1>30</mu1>
    <mu2>30</mu2>
    <kp>1e50</kp>
    <kd>1e50</kd>
    <material>Gazebo/Grey</material>
  </gazebo>
  <gazebo reference="roller_LF_14_link">
    <selfCollide>true</selfCollide>
    <gravity>true</gravity>
    <mu1>30</mu1>
    <mu2>30</mu2>
    <kp>1e50</kp>
    <kd>1e50</kd>
    <material>Gazebo/Grey</material>
  </gazebo>
  <gazebo reference="roller_LF_15_link">
    <selfCollide>true</selfCollide>
    <gravity>true</gravity>
    <mu1>30</mu1>
    <mu2>30</mu2>
    <kp>1e50</kp>
    <kd>1e50</kd>
    <material>Gazebo/Grey</material>
  </gazebo>
  <gazebo reference="roller_LF_16_link">
    <selfCollide>true</selfCollide>
    <gravity>true</gravity>
    <mu1>30</mu1>
    <mu2>30</mu2>
    <kp>1e50</kp>
    <kd>1e50</kd>
    <material>Gazebo/Grey</material>
  </gazebo>
  <gazebo reference="roller_RF_1_link">
    <selfCollide>true</selfCollide>
    <gravity>true</gravity>
    <mu1>30</mu1>
    <mu2>30</mu2>
    <kp>1e50</kp>
    <kd>1e50</kd>
    <material>Gazebo/Grey</material>
  </gazebo>
  <gazebo reference="roller_RF_2_link">
    <selfCollide>true</selfCollide>
    <gravity>true</gravity>
    <mu1>30</mu1>
    <mu2>30</mu2>
    <kp>1e50</kp>
    <kd>1e50</kd>
    <material>Gazebo/Grey</material>
  </gazebo>
  <gazebo reference="roller_RF_3_link">
    <selfCollide>true</selfCollide>
    <gravity>true</gravity>
    <mu1>30</mu1>
    <mu2>30</mu2>
    <kp>1e50</kp>
    <kd>1e50</kd>
    <material>Gazebo/Grey</material>
  </gazebo>
  <gazebo reference="roller_RF_4_link">
    <selfCollide>true</selfCollide>
    <gravity>true</gravity>
    <mu1>30</mu1>
    <mu2>30</mu2>
    <kp>1e50</kp>
    <kd>1e50</kd>
    <material>Gazebo/Grey</material>
  </gazebo>
  <gazebo reference="roller_RF_5_link">
    <selfCollide>true</selfCollide>
    <gravity>true</gravity>
    <mu1>30</mu1>
    <mu2>30</mu2>
    <kp>1e50</kp>
    <kd>1e50</kd>
    <material>Gazebo/Grey</material>
  </gazebo>
  <gazebo reference="roller_RF_6_link">
    <selfCollide>true</selfCollide>
    <gravity>true</gravity>
    <mu1>30</mu1>
    <mu2>30</mu2>
    <kp>1e50</kp>
    <kd>1e50</kd>
    <material>Gazebo/Grey</material>
  </gazebo>
  <gazebo reference="roller_RF_7_link">
    <selfCollide>true</selfCollide>
    <gravity>true</gravity>
    <mu1>30</mu1>
    <mu2>30</mu2>
    <kp>1e50</kp>
    <kd>1e50</kd>
    <material>Gazebo/Grey</material>
  </gazebo>
  <gazebo reference="roller_RF_8_link">
    <selfCollide>true</selfCollide>
    <gravity>true</gravity>
    <mu1>30</mu1>
    <mu2>30</mu2>
    <kp>1e50</kp>
    <kd>1e50</kd>
    <material>Gazebo/Grey</material>
  </gazebo>
  <gazebo reference="roller_RF_9_link">
    <selfCollide>true</selfCollide>
    <gravity>true</gravity>
    <mu1>30</mu1>
    <mu2>30</mu2>
    <kp>1e50</kp>
    <kd>1e50</kd>
    <material>Gazebo/Grey</material>
  </gazebo>
  <gazebo reference="roller_RF_10_link">
    <selfCollide>true</selfCollide>
    <gravity>true</gravity>
    <mu1>30</mu1>
    <mu2>30</mu2>
    <kp>1e50</kp>
    <kd>1e50</kd>
    <material>Gazebo/Grey</material>
  </gazebo>
  <gazebo reference="roller_RF_11_link">
    <selfCollide>true</selfCollide>
    <gravity>true</gravity>
    <mu1>30</mu1>
    <mu2>30</mu2>
    <kp>1e50</kp>
    <kd>1e50</kd>
    <material>Gazebo/Grey</material>
  </gazebo>
  <gazebo reference="roller_RF_12_link">
    <selfCollide>true</selfCollide>
    <gravity>true</gravity>
    <mu1>30</mu1>
    <mu2>30</mu2>
    <kp>1e50</kp>
    <kd>1e50</kd>
    <material>Gazebo/Grey</material>
  </gazebo>
  <gazebo reference="roller_RF_13_link">
    <selfCollide>true</selfCollide>
    <gravity>true</gravity>
    <mu1>30</mu1>
    <mu2>30</mu2>
    <kp>1e50</kp>
    <kd>1e50</kd>
    <material>Gazebo/Grey</material>
  </gazebo>
  <gazebo reference="roller_RF_14_link">
    <selfCollide>true</selfCollide>
    <gravity>true</gravity>
    <mu1>30</mu1>
    <mu2>30</mu2>
    <kp>1e50</kp>
    <kd>1e50</kd>
    <material>Gazebo/Grey</material>
  </gazebo>
  <gazebo reference="roller_RF_15_link">
    <selfCollide>true</selfCollide>
    <gravity>true</gravity>
    <mu1>30</mu1>
    <mu2>30</mu2>
    <kp>1e50</kp>
    <kd>1e50</kd>
    <material>Gazebo/Grey</material>
  </gazebo>
  <gazebo reference="roller_RF_16_link">
    <selfCollide>true</selfCollide>
    <gravity>true</gravity>
    <mu1>30</mu1>
    <mu2>30</mu2>
    <kp>1e50</kp>
    <kd>1e50</kd>
    <material>Gazebo/Grey</material>
  </gazebo>
  <gazebo reference="roller_RB_1_link">
    <selfCollide>true</selfCollide>
    <gravity>true</gravity>
    <mu1>30</mu1>
    <mu2>30</mu2>
    <kp>1e50</kp>
    <kd>1e50</kd>
    <material>Gazebo/Grey</material>
  </gazebo>
  <gazebo reference="roller_RB_2_link">
    <selfCollide>true</selfCollide>
    <gravity>true</gravity>
    <mu1>30</mu1>
    <mu2>30</mu2>
    <kp>1e50</kp>
    <kd>1e50</kd>
    <material>Gazebo/Grey</material>
  </gazebo>
  <gazebo reference="roller_RB_3_link">
    <selfCollide>true</selfCollide>
    <gravity>true</gravity>
    <mu1>30</mu1>
    <mu2>30</mu2>
    <kp>1e50</kp>
    <kd>1e50</kd>
    <material>Gazebo/Grey</material>
  </gazebo>
  <gazebo reference="roller_RB_4_link">
    <selfCollide>true</selfCollide>
    <gravity>true</gravity>
    <mu1>30</mu1>
    <mu2>30</mu2>
    <kp>1e50</kp>
    <kd>1e50</kd>
    <material>Gazebo/Grey</material>
  </gazebo>
  <gazebo reference="roller_RB_5_link">
    <selfCollide>true</selfCollide>
    <gravity>true</gravity>
    <mu1>30</mu1>
    <mu2>30</mu2>
    <kp>1e50</kp>
    <kd>1e50</kd>
    <material>Gazebo/Grey</material>
  </gazebo>
  <gazebo reference="roller_RB_6_link">
    <selfCollide>true</selfCollide>
    <gravity>true</gravity>
    <mu1>30</mu1>
    <mu2>30</mu2>
    <kp>1e50</kp>
    <kd>1e50</kd>
    <material>Gazebo/Grey</material>
  </gazebo>
  <gazebo reference="roller_RB_7_link">
    <selfCollide>true</selfCollide>
    <gravity>true</gravity>
    <mu1>30</mu1>
    <mu2>30</mu2>
    <kp>1e50</kp>
    <kd>1e50</kd>
    <material>Gazebo/Grey</material>
  </gazebo>
  <gazebo reference="roller_RB_8_link">
    <selfCollide>true</selfCollide>
    <gravity>true</gravity>
    <mu1>30</mu1>
    <mu2>30</mu2>
    <kp>1e50</kp>
    <kd>1e50</kd>
    <material>Gazebo/Grey</material>
  </gazebo>
  <gazebo reference="roller_RB_9_link">
    <selfCollide>true</selfCollide>
    <gravity>true</gravity>
    <mu1>30</mu1>
    <mu2>30</mu2>
    <kp>1e50</kp>
    <kd>1e50</kd>
    <material>Gazebo/Grey</material>
  </gazebo>
  <gazebo reference="roller_RB_10_link">
    <selfCollide>true</selfCollide>
    <gravity>true</gravity>
    <mu1>30</mu1>
    <mu2>30</mu2>
    <kp>1e50</kp>
    <kd>1e50</kd>
    <material>Gazebo/Grey</material>
  </gazebo>
  <gazebo reference="roller_RB_11_link">
    <selfCollide>true</selfCollide>
    <gravity>true</gravity>
    <mu1>30</mu1>
    <mu2>30</mu2>
    <kp>1e50</kp>
    <kd>1e50</kd>
    <material>Gazebo/Grey</material>
  </gazebo>
  <gazebo reference="roller_RB_12_link">
    <selfCollide>true</selfCollide>
    <gravity>true</gravity>
    <mu1>30</mu1>
    <mu2>30</mu2>
    <kp>1e50</kp>
    <kd>1e50</kd>
    <material>Gazebo/Grey</material>
  </gazebo>
  <gazebo reference="roller_RB_13_link">
    <selfCollide>true</selfCollide>
    <gravity>true</gravity>
    <mu1>30</mu1>
    <mu2>30</mu2>
    <kp>1e50</kp>
    <kd>1e50</kd>
    <material>Gazebo/Grey</material>
  </gazebo>
  <gazebo reference="roller_RB_14_link">
    <selfCollide>true</selfCollide>
    <gravity>true</gravity>
    <mu1>30</mu1>
    <mu2>30</mu2>
    <kp>1e50</kp>
    <kd>1e50</kd>
    <material>Gazebo/Grey</material>
  </gazebo>
  <gazebo reference="roller_RB_15_link">
    <selfCollide>true</selfCollide>
    <gravity>true</gravity>
    <mu1>30</mu1>
    <mu2>30</mu2>
    <kp>1e50</kp>
    <kd>1e50</kd>
    <material>Gazebo/Grey</material>
  </gazebo>
  <gazebo reference="roller_RB_16_link">
    <selfCollide>true</selfCollide>
    <gravity>true</gravity>
    <mu1>30</mu1>
    <mu2>30</mu2>
    <kp>1e50</kp>
    <kd>1e50</kd>
    <material>Gazebo/Grey</material>
  </gazebo>
  <gazebo reference="roller_LB_1_link">
    <selfCollide>true</selfCollide>
    <gravity>true</gravity>
    <mu1>30</mu1>
    <mu2>30</mu2>
    <kp>1e50</kp>
    <kd>1e50</kd>
    <material>Gazebo/Grey</material>
  </gazebo>
  <gazebo reference="roller_LB_2_link">
    <selfCollide>true</selfCollide>
    <gravity>true</gravity>
    <mu1>30</mu1>
    <mu2>30</mu2>
    <kp>1e50</kp>
    <kd>1e50</kd>
    <material>Gazebo/Grey</material>
  </gazebo>
  <gazebo reference="roller_LB_3_link">
    <selfCollide>true</selfCollide>
    <gravity>true</gravity>
    <mu1>30</mu1>
    <mu2>30</mu2>
    <kp>1e50</kp>
    <kd>1e50</kd>
    <material>Gazebo/Grey</material>
  </gazebo>
  <gazebo reference="roller_LB_4_link">
    <selfCollide>true</selfCollide>
    <gravity>true</gravity>
    <mu1>30</mu1>
    <mu2>30</mu2>
    <kp>1e50</kp>
    <kd>1e50</kd>
    <material>Gazebo/Grey</material>
  </gazebo>
  <gazebo reference="roller_LB_5_link">
    <selfCollide>true</selfCollide>
    <gravity>true</gravity>
    <mu1>30</mu1>
    <mu2>30</mu2>
    <kp>1e50</kp>
    <kd>1e50</kd>
    <material>Gazebo/Grey</material>
  </gazebo>
  <gazebo reference="roller_LB_6_link">
    <selfCollide>true</selfCollide>
    <gravity>true</gravity>
    <mu1>30</mu1>
    <mu2>30</mu2>
    <kp>1e50</kp>
    <kd>1e50</kd>
    <material>Gazebo/Grey</material>
  </gazebo>
  <gazebo reference="roller_LB_7_link">
    <selfCollide>true</selfCollide>
    <gravity>true</gravity>
    <mu1>30</mu1>
    <mu2>30</mu2>
    <kp>1e50</kp>
    <kd>1e50</kd>
    <material>Gazebo/Grey</material>
  </gazebo>
  <gazebo reference="roller_LB_8_link">
    <selfCollide>true</selfCollide>
    <gravity>true</gravity>
    <mu1>30</mu1>
    <mu2>30</mu2>
    <kp>1e50</kp>
    <kd>1e50</kd>
    <material>Gazebo/Grey</material>
  </gazebo>
  <gazebo reference="roller_LB_9_link">
    <selfCollide>true</selfCollide>
    <gravity>true</gravity>
    <mu1>30</mu1>
    <mu2>30</mu2>
    <kp>1e50</kp>
    <kd>1e50</kd>
    <material>Gazebo/Grey</material>
  </gazebo>
  <gazebo reference="roller_LB_10_link">
    <selfCollide>true</selfCollide>
    <gravity>true</gravity>
    <mu1>30</mu1>
    <mu2>30</mu2>
    <kp>1e50</kp>
    <kd>1e50</kd>
    <material>Gazebo/Grey</material>
  </gazebo>
  <gazebo reference="roller_LB_11_link">
    <selfCollide>true</selfCollide>
    <gravity>true</gravity>
    <mu1>30</mu1>
    <mu2>30</mu2>
    <kp>1e50</kp>
    <kd>1e50</kd>
    <material>Gazebo/Grey</material>
  </gazebo>
  <gazebo reference="roller_LB_12_link">
    <selfCollide>true</selfCollide>
    <gravity>true</gravity>
    <mu1>30</mu1>
    <mu2>30</mu2>
    <kp>1e50</kp>
    <kd>1e50</kd>
    <material>Gazebo/Grey</material>
  </gazebo>
  <gazebo reference="roller_LB_13_link">
    <selfCollide>true</selfCollide>
    <gravity>true</gravity>
    <mu1>30</mu1>
    <mu2>30</mu2>
    <kp>1e50</kp>
    <kd>1e50</kd>
    <material>Gazebo/Grey</material>
  </gazebo>
  <gazebo reference="roller_LB_14_link">
    <selfCollide>true</selfCollide>
    <gravity>true</gravity>
    <mu1>30</mu1>
    <mu2>30</mu2>
    <kp>1e50</kp>
    <kd>1e50</kd>
    <material>Gazebo/Grey</material>
  </gazebo>
  <gazebo reference="roller_LB_15_link">
    <selfCollide>true</selfCollide>
    <gravity>true</gravity>
    <mu1>30</mu1>
    <mu2>30</mu2>
    <kp>1e50</kp>
    <kd>1e50</kd>
    <material>Gazebo/Grey</material>
  </gazebo>
  <gazebo reference="roller_LB_16_link">
    <selfCollide>true</selfCollide>
    <gravity>true</gravity>
    <mu1>30</mu1>
    <mu2>30</mu2>
    <kp>1e50</kp>
    <kd>1e50</kd>
    <material>Gazebo/Grey</material>
  </gazebo>
  <gazebo reference="base_link">
    <material>Gazebo/Grey</material>
    <self_collide>true</self_collide>
    <gravity>true</gravity>
  </gazebo>
  <gazebo reference="link1">
    <material>Gazebo/Grey</material>
    <self_collide>true</self_collide>
    <gravity>true</gravity>
  </gazebo>
  <gazebo reference="link2">
    <material>Gazebo/Grey</material>
    <self_collide>true</self_collide>
    <gravity>true</gravity>
  </gazebo>
  <gazebo reference="link3">
    <material>Gazebo/Grey</material>
    <self_collide>true</self_collide>
    <gravity>true</gravity>
  </gazebo>
  <gazebo reference="link4">
    <material>Gazebo/Grey</material>
    <self_collide>true</self_collide>
    <gravity>true</gravity>
  </gazebo>
  <gazebo reference="link5">
    <material>Gazebo/Grey</material>
    <self_collide>true</self_collide>
    <gravity>true</gravity>
  </gazebo>
  <gazebo reference="link6">
    <material>Gazebo/Grey</material>
    <self_collide>true</self_collide>
    <gravity>true</gravity>
  </gazebo>
  <gazebo reference="link7">
    <material>Gazebo/Grey</material>
    <self_collide>true</self_collide>
    <gravity>true</gravity>
  </gazebo>
  <gazebo reference="left_z_link">
    <material>Gazebo/Grey</material>
    <self_collide>true</self_collide>
    <gravity>true</gravity>
  </gazebo>
  <gazebo reference="left_x_link">
    <material>Gazebo/Grey</material>
    <self_collide>true</self_collide>
    <gravity>true</gravity>
  </gazebo>
  <gazebo reference="left_yaw_link">
    <material>Gazebo/Grey</material>
    <self_collide>true</self_collide>
    <gravity>true</gravity>
  </gazebo>
  <gazebo reference="right_z_link">
    <material>Gazebo/Grey</material>
    <self_collide>true</self_collide>
    <gravity>true</gravity>
  </gazebo>
  <gazebo reference="right_x_link">
    <material>Gazebo/Grey</material>
    <self_collide>true</self_collide>
    <gravity>true</gravity>
  </gazebo>
  <gazebo reference="right_yaw_link">
    <material>Gazebo/Grey</material>
    <self_collide>true</self_collide>
    <gravity>true</gravity>
  </gazebo>
  <gazebo reference="engineer_depth_camera">
    <selfCollide>false</selfCollide>
    <gravity>false</gravity>
    <mu1>30</mu1>
    <mu2>30</mu2>
    <kp>1e50</kp>
    <kd>1e50</kd>
    <material>Gazebo/White</material>
  </gazebo>
</robot>
