<?xml version="1.0" ?>
<!-- =================================================================================== -->
<!-- |    This document was autogenerated by xacro from src/engineer/engineer_description/urdf/exchanger/engineer_exchanger.urdf.xacro | -->
<!-- |    EDITING THIS FILE BY HAND IS NOT RECOMMENDED                                 | -->
<!-- =================================================================================== -->
<robot name="wheel">
  <link name="wheel">
    <visual>
      <origin rpy="0 0 0" xyz="0 0 0"/>
      <geometry>
        <mesh filename="../../../engineer_description/meshes/left-threaded_mecanum_wheel_wheel.STL"/>
      </geometry>
      <material name="">
        <color rgba="0.1 0.1 0.1 1"/>
      </material>
    </visual>
    <collision>
      <origin rpy="0 0 0" xyz="0 0 0"/>
      <geometry>
        <mesh filename="package://engineer_description/meshes/left-threaded_mecanum_wheel_wheel.STL"/>
      </geometry>
    </collision>
  </link>

  <joint name="wheel_joint1" type="continuous">
    <parent link="wheel"/>
    <child link="roller_1"/>
    <origin rpy="0.7854 0 0.4988" xyz="0.05900 0.03166 -0.0019"/> <!--right-threaded-->
    <!-- <origin rpy="-0.7854 0 0.8915" xyz="0.04206599 0.052094 0.0019"/> -->
    <axis xyz="0 0 1"/>
  </joint>

<!-- 0.066957864 -->
  <link name="roller_1">
    <visual>
      <origin rpy="0 0 0" xyz="0 0 0"/>
      <geometry>
        <mesh filename="package://engineer_description/meshes/roller.STL"/>
      </geometry>
      <material name="">
        <color rgba="0.1 0.1 0.1 1"/>
      </material>
    </visual>
    <collision>
      <origin rpy="0 0 0" xyz="0 0 0"/>
      <geometry>
        <mesh filename="package://engineer_description/meshes/roller.STL"/>
      </geometry>
    </collision>
  </link>

  <joint name="wheel_joint2" type="continuous">
    <parent link="wheel"/>
    <child link="roller_2"/>
    <origin rpy="0.7854 0 0.8915" xyz="0.04206599 0.052094 -0.0019"/>
    <axis xyz="0 0 1"/>
  </joint>

  <link name="roller_2">
    <visual>
      <origin rpy="0 0 0" xyz="0 0 0"/>
      <geometry>
        <mesh filename="package://engineer_description/meshes/roller.STL"/>
      </geometry>
      <material name="">
        <color rgba="0.1 0.1 0.1 1"/>
      </material>
    </visual>
    <collision>
      <origin rpy="0 0 0" xyz="0 0 0"/>
      <geometry>
        <mesh filename="package://engineer_description/meshes/roller.STL"/>
      </geometry>
    </collision>
  </link>
</robot>
